Workbook

Sheet Player_Stats_All_Time
A1: player_name | B1: games_played | C1: wins | D1: losses | E1: winrate | F1: total_goals | G1: avg_goals | H1: total_assists | I1: avg_assists | J1: total_damage | K1: avg_damage | L1: total_score | M1: avg_score | N1: avg_dps | O1: ELO_current | P1: ELO_change_10_matches | Q1: ELO_peak
A2: =IFERROR(__xludf.DUMMYFUNCTION("SORT(UNIQUE(FILTER(Raw!L2:L1000, Raw!L2:L1000<>""""))) "),"Aferdita") -> Aferdita | B2: {=IF(A2:A1000="", , COUNTIF(Raw!L:L, A2:A1000) )} -> 29 | C2: {=IF(A2:A1000="", , COUNTIFS(Raw!L:L, A2:A1000, Raw!I:I, "win") )} -> 13 | D2: {=IF(A2:A1000="", , COUNTIFS(Raw!L:L, A2:A1000, Raw!I:I, "loss") )} -> 16 | E2: {=IF(A2:A1000="", , IF(B2:B1000=0, , C2:C1000 / B2:B1000) )} -> 0.44827586 | F2: {=IF(A2:A1000="", , SUMIF(Raw!L:L, A2:A1000, Raw!M:M) )} -> 54 | G2: {=IF(A2:A1000="", , IF(B2:B1000=0, , F2:F1000 / B2:B1000) )} -> 1.862069 | H2: {=IF(A2:A1000="", , SUMIF(Raw!L:L, A2:A1000, Raw!O:O) )} -> 10 | I2: {=IF(A2:A1000="", , IF(B2:B1000=0, , H2:H1000 / B2:B1000) )} -> 0.34482759 | J2: {=IF(A2:A1000="", , SUMIF(Raw!L:L, A2:A1000, Raw!P:P) )} -> 46378 | K2: {=IF(A2:A1000="", , IF(B2:B1000=0, , J2:J1000 / B2:B1000) )} -> 1599.2414 | L2: {=IF(A2:A1000="", , SUMIF(Raw!L:L, A2:A1000, Raw!Q:Q) )} -> 2755 | M2: {=IF(A2:A1000="", , IF(B2:B1000=0, , L2:L1000 / B2:B1000) )} -> 95 | N2: {=IF(A2:A1000="", , IF( SUMIF(Raw!L:L, A2:A1000, Raw!E:E)=0, , SUMIF(Raw!L:L, A2:A1000, Raw!P:P) / SUMIF(Raw!L:L, A2:A1000, Raw!E:E) ) )} -> 1.638567 | O2: =IFERROR(__xludf.DUMMYFUNCTION("IFERROR(INDEX(FILTER(Elo_Player_All!$Q:$Q,Elo_Player_All!$C:$C=A2),ROWS(FILTER(Elo_Player_All!$Q:$Q,Elo_Player_All!$C:$C=A2)),1),1500)"),1484.0) -> 1484 | P2: =IFERROR(__xludf.DUMMYFUNCTION("IF(A2="""","""",IFERROR(SUM(QUERY(FILTER(Elo_Player_All!P:P,Elo_Player_All!C:C=A2),""LIMIT 10 OFFSET ""&MAX(0,COUNTIF(Elo_Player_All!C:C,A2)-10))),""""))"),-47.0) -> -47 | Q2: =IFERROR(__xludf.DUMMYFUNCTION("IF(A2="""","""",IFERROR(MAX(FILTER(Elo_Player_All!$Q:$Q,Elo_Player_All!$C:$C=A2)),""""))"),1543.0) -> 1543
A3: =IFERROR(__xludf.DUMMYFUNCTION("""COMPUTED_VALUE"""),"Anbuu") -> Anbuu | B3: 12 | C3: 8 | D3: 4 | E3: 0.66666667 | F3: 6 | G3: 0.5 | H3: 4 | I3: 0.33333333 | J3: 43928 | K3: 3660.6667 | L3: 1634 | M3: 136.16667 | N3: 3.4711972 | O3: =IFERROR(__xludf.DUMMYFUNCTION("IFERROR(INDEX(FILTER(Elo_Player_All!$Q:$Q,Elo_Player_All!$C:$C=A3),ROWS(FILTER(Elo_Player_All!$Q:$Q,Elo_Player_All!$C:$C=A3)),1),1500)"),1553.0) -> 1553 | P3: =IFERROR(__xludf.DUMMYFUNCTION("IF(A3="""","""",IFERROR(SUM(QUERY(FILTER(Elo_Player_All!P:P,Elo_Player_All!C:C=A3),""LIMIT 10 OFFSET ""&MAX(0,COUNTIF(Elo_Player_All!C:C,A3)-10))),""""))"),53.0) -> 53 | Q3: =IFERROR(__xludf.DUMMYFUNCTION("IF(A3="""","""",IFERROR(MAX(FILTER(Elo_Player_All!$Q:$Q,Elo_Player_All!$C:$C=A3)),""""))"),1572.0) -> 1572
A4: =IFERROR(__xludf.DUMMYFUNCTION("""COMPUTED_VALUE"""),"Kesny") -> Kesny | B4: 65 | C4: 23 | D4: 42 | E4: 0.35384615 | F4: 224 | G4: 3.4461538 | H4: 64 | I4: 0.98461538 | J4: 117398 | K4: 1806.1231 | L4: 9071 | M4: 139.55385 | N4: 1.9907414 | O4: =IFERROR(__xludf.DUMMYFUNCTION("IFERROR(INDEX(FILTER(Elo_Player_All!$Q:$Q,Elo_Player_All!$C:$C=A4),ROWS(FILTER(Elo_Player_All!$Q:$Q,Elo_Player_All!$C:$C=A4)),1),1500)"),1427.0) -> 1427 | P4: =IFERROR(__xludf.DUMMYFUNCTION("IF(A4="""","""",IFERROR(SUM(QUERY(FILTER(Elo_Player_All!P:P,Elo_Player_All!C:C=A4),""LIMIT 10 OFFSET ""&MAX(0,COUNTIF(Elo_Player_All!C:C,A4)-10))),""""))"),26.0) -> 26 | Q4: =IFERROR(__xludf.DUMMYFUNCTION("IF(A4="""","""",IFERROR(MAX(FILTER(Elo_Player_All!$Q:$Q,Elo_Player_All!$C:$C=A4)),""""))"),1542.0) -> 1542
A5: =IFERROR(__xludf.DUMMYFUNCTION("""COMPUTED_VALUE"""),"Malena") -> Malena | B5: 97 | C5: 52 | D5: 45 | E5: 0.53608247 | F5: 515 | G5: 5.3092784 | H5: 33 | I5: 0.34020619 | J5: 211553 | K5: 2180.9588 | L5: 15066 | M5: 155.31959 | N5: 2.5954239 | O5: =IFERROR(__xludf.DUMMYFUNCTION("IFERROR(INDEX(FILTER(Elo_Player_All!$Q:$Q,Elo_Player_All!$C:$C=A5),ROWS(FILTER(Elo_Player_All!$Q:$Q,Elo_Player_All!$C:$C=A5)),1),1500)"),1582.0) -> 1582 | P5: =IFERROR(__xludf.DUMMYFUNCTION("IF(A5="""","""",IFERROR(SUM(QUERY(FILTER(Elo_Player_All!P:P,Elo_Player_All!C:C=A5),""LIMIT 10 OFFSET ""&MAX(0,COUNTIF(Elo_Player_All!C:C,A5)-10))),""""))"),19.0) -> 19 | Q5: =IFERROR(__xludf.DUMMYFUNCTION("IF(A5="""","""",IFERROR(MAX(FILTER(Elo_Player_All!$Q:$Q,Elo_Player_All!$C:$C=A5)),""""))"),1632.0) -> 1632
A6: =IFERROR(__xludf.DUMMYFUNCTION("""COMPUTED_VALUE"""),"Nebus.") -> Nebus. | B6: 93 | C6: 61 | D6: 32 | E6: 0.65591398 | F6: 328 | G6: 3.5268817 | H6: 37 | I6: 0.39784946 | J6: 233687 | K6: 2512.7634 | L6: 13269 | M6: 142.67742 | N6: 2.9824895 | O6: =IFERROR(__xludf.DUMMYFUNCTION("IFERROR(INDEX(FILTER(Elo_Player_All!$Q:$Q,Elo_Player_All!$C:$C=A6),ROWS(FILTER(Elo_Player_All!$Q:$Q,Elo_Player_All!$C:$C=A6)),1),1500)"),1590.0) -> 1590 | P6: =IFERROR(__xludf.DUMMYFUNCTION("IF(A6="""","""",IFERROR(SUM(QUERY(FILTER(Elo_Player_All!P:P,Elo_Player_All!C:C=A6),""LIMIT 10 OFFSET ""&MAX(0,COUNTIF(Elo_Player_All!C:C,A6)-10))),""""))"),0.0) -> 0 | Q6: =IFERROR(__xludf.DUMMYFUNCTION("IF(A6="""","""",IFERROR(MAX(FILTER(Elo_Player_All!$Q:$Q,Elo_Player_All!$C:$C=A6)),""""))"),1625.0) -> 1625
A7: =IFERROR(__xludf.DUMMYFUNCTION("""COMPUTED_VALUE"""),"Tess1509") -> Tess1509 | B7: 55 | C7: 12 | D7: 43 | E7: 0.21818182 | F7: 59 | G7: 1.0727273 | H7: 22 | I7: 0.4 | J7: 115353 | K7: 2097.3273 | L7: 5045 | M7: 91.727273 | N7: 2.4975209 | O7: =IFERROR(__xludf.DUMMYFUNCTION("IFERROR(INDEX(FILTER(Elo_Player_All!$Q:$Q,Elo_Player_All!$C:$C=A7),ROWS(FILTER(Elo_Player_All!$Q:$Q,Elo_Player_All!$C:$C=A7)),1),1500)"),1359.0) -> 1359 | P7: =IFERROR(__xludf.DUMMYFUNCTION("IF(A7="""","""",IFERROR(SUM(QUERY(FILTER(Elo_Player_All!P:P,Elo_Player_All!C:C=A7),""LIMIT 10 OFFSET ""&MAX(0,COUNTIF(Elo_Player_All!C:C,A7)-10))),""""))"),-55.0) -> -55 | Q7: =IFERROR(__xludf.DUMMYFUNCTION("IF(A7="""","""",IFERROR(MAX(FILTER(Elo_Player_All!$Q:$Q,Elo_Player_All!$C:$C=A7)),""""))"),1485.0) -> 1485
A8: =IFERROR(__xludf.DUMMYFUNCTION("""COMPUTED_VALUE"""),"Troniix") -> Troniix | B8: 5 | C8: 0 | D8: 5 | E8: 0 | F8: 0 | G8: 0 | H8: 2 | I8: 0.4 | J8: 9856 | K8: 1971.2 | L8: 339 | M8: 67.8 | N8: 2.1970575 | O8: =IFERROR(__xludf.DUMMYFUNCTION("IFERROR(INDEX(FILTER(Elo_Player_All!$Q:$Q,Elo_Player_All!$C:$C=A8),ROWS(FILTER(Elo_Player_All!$Q:$Q,Elo_Player_All!$C:$C=A8)),1),1500)"),1431.0) -> 1431 | P8: =IFERROR(__xludf.DUMMYFUNCTION("IF(A8="""","""",IFERROR(SUM(QUERY(FILTER(Elo_Player_All!P:P,Elo_Player_All!C:C=A8),""LIMIT 10 OFFSET ""&MAX(0,COUNTIF(Elo_Player_All!C:C,A8)-10))),""""))"),-69.0) -> -69 | Q8: =IFERROR(__xludf.DUMMYFUNCTION("IF(A8="""","""",IFERROR(MAX(FILTER(Elo_Player_All!$Q:$Q,Elo_Player_All!$C:$C=A8)),""""))"),1485.0) -> 1485
A9: =IFERROR(__xludf.DUMMYFUNCTION("""COMPUTED_VALUE"""),"ZeroO") -> ZeroO | B9: 92 | C9: 55 | D9: 37 | E9: 0.59782609 | F9: 451 | G9: 4.9021739 | H9: 46 | I9: 0.5 | J9: 199745 | K9: 2171.1413 | L9: 13792 | M9: 149.91304 | N9: 2.5809849 | O9: =IFERROR(__xludf.DUMMYFUNCTION("IFERROR(INDEX(FILTER(Elo_Player_All!$Q:$Q,Elo_Player_All!$C:$C=A9),ROWS(FILTER(Elo_Player_All!$Q:$Q,Elo_Player_All!$C:$C=A9)),1),1500)"),1547.0) -> 1547 | P9: =IFERROR(__xludf.DUMMYFUNCTION("IF(A9="""","""",IFERROR(SUM(QUERY(FILTER(Elo_Player_All!P:P,Elo_Player_All!C:C=A9),""LIMIT 10 OFFSET ""&MAX(0,COUNTIF(Elo_Player_All!C:C,A9)-10))),""""))"),14.0) -> 14 | Q9: =IFERROR(__xludf.DUMMYFUNCTION("IF(A9="""","""",IFERROR(MAX(FILTER(Elo_Player_All!$Q:$Q,Elo_Player_All!$C:$C=A9)),""""))"),1603.0) -> 1603
O10: =IFERROR(__xludf.DUMMYFUNCTION("IFERROR(INDEX(FILTER(Elo_Player_All!$Q:$Q,Elo_Player_All!$C:$C=A10),ROWS(FILTER(Elo_Player_All!$Q:$Q,Elo_Player_All!$C:$C=A10)),1),1500)"),"") | P10: =IFERROR(__xludf.DUMMYFUNCTION("IF(A10="""","""",IFERROR(SUM(QUERY(FILTER(Elo_Player_All!P:P,Elo_Player_All!C:C=A10),""LIMIT 10 OFFSET ""&MAX(0,COUNTIF(Elo_Player_All!C:C,A10)-10))),""""))"),"") | Q10: =IFERROR(__xludf.DUMMYFUNCTION("IF(A10="""","""",IFERROR(MAX(FILTER(Elo_Player_All!$Q:$Q,Elo_Player_All!$C:$C=A10)),""""))"),"")
O11: =IFERROR(__xludf.DUMMYFUNCTION("IFERROR(INDEX(FILTER(Elo_Player_All!$Q:$Q,Elo_Player_All!$C:$C=A11),ROWS(FILTER(Elo_Player_All!$Q:$Q,Elo_Player_All!$C:$C=A11)),1),1500)"),"") | P11: =IFERROR(__xludf.DUMMYFUNCTION("IF(A11="""","""",IFERROR(SUM(QUERY(FILTER(Elo_Player_All!P:P,Elo_Player_All!C:C=A11),""LIMIT 10 OFFSET ""&MAX(0,COUNTIF(Elo_Player_All!C:C,A11)-10))),""""))"),"") | Q11: =IFERROR(__xludf.DUMMYFUNCTION("IF(A11="""","""",IFERROR(MAX(FILTER(Elo_Player_All!$Q:$Q,Elo_Player_All!$C:$C=A11)),""""))"),"")
O12: =IFERROR(__xludf.DUMMYFUNCTION("IFERROR(INDEX(FILTER(Elo_Player_All!$Q:$Q,Elo_Player_All!$C:$C=A12),ROWS(FILTER(Elo_Player_All!$Q:$Q,Elo_Player_All!$C:$C=A12)),1),1500)"),"") | P12: =IFERROR(__xludf.DUMMYFUNCTION("IF(A12="""","""",IFERROR(SUM(QUERY(FILTER(Elo_Player_All!P:P,Elo_Player_All!C:C=A12),""LIMIT 10 OFFSET ""&MAX(0,COUNTIF(Elo_Player_All!C:C,A12)-10))),""""))"),"") | Q12: =IFERROR(__xludf.DUMMYFUNCTION("IF(A12="""","""",IFERROR(MAX(FILTER(Elo_Player_All!$Q:$Q,Elo_Player_All!$C:$C=A12)),""""))"),"")
O13: =IFERROR(__xludf.DUMMYFUNCTION("IFERROR(INDEX(FILTER(Elo_Player_All!$Q:$Q,Elo_Player_All!$C:$C=A13),ROWS(FILTER(Elo_Player_All!$Q:$Q,Elo_Player_All!$C:$C=A13)),1),1500)"),"") | P13: =IFERROR(__xludf.DUMMYFUNCTION("IF(A13="""","""",IFERROR(SUM(QUERY(FILTER(Elo_Player_All!P:P,Elo_Player_All!C:C=A13),""LIMIT 10 OFFSET ""&MAX(0,COUNTIF(Elo_Player_All!C:C,A13)-10))),""""))"),"") | Q13: =IFERROR(__xludf.DUMMYFUNCTION("IF(A13="""","""",IFERROR(MAX(FILTER(Elo_Player_All!$Q:$Q,Elo_Player_All!$C:$C=A13)),""""))"),"")
O14: =IFERROR(__xludf.DUMMYFUNCTION("IFERROR(INDEX(FILTER(Elo_Player_All!$Q:$Q,Elo_Player_All!$C:$C=A14),ROWS(FILTER(Elo_Player_All!$Q:$Q,Elo_Player_All!$C:$C=A14)),1),1500)"),"") | P14: =IFERROR(__xludf.DUMMYFUNCTION("IF(A14="""","""",IFERROR(SUM(QUERY(FILTER(Elo_Player_All!P:P,Elo_Player_All!C:C=A14),""LIMIT 10 OFFSET ""&MAX(0,COUNTIF(Elo_Player_All!C:C,A14)-10))),""""))"),"") | Q14: =IFERROR(__xludf.DUMMYFUNCTION("IF(A14="""","""",IFERROR(MAX(FILTER(Elo_Player_All!$Q:$Q,Elo_Player_All!$C:$C=A14)),""""))"),"")
O15: =IFERROR(__xludf.DUMMYFUNCTION("IFERROR(INDEX(FILTER(Elo_Player_All!$Q:$Q,Elo_Player_All!$C:$C=A15),ROWS(FILTER(Elo_Player_All!$Q:$Q,Elo_Player_All!$C:$C=A15)),1),1500)"),"") | P15: =IFERROR(__xludf.DUMMYFUNCTION("IF(A15="""","""",IFERROR(SUM(QUERY(FILTER(Elo_Player_All!P:P,Elo_Player_All!C:C=A15),""LIMIT 10 OFFSET ""&MAX(0,COUNTIF(Elo_Player_All!C:C,A15)-10))),""""))"),"") | Q15: =IFERROR(__xludf.DUMMYFUNCTION("IF(A15="""","""",IFERROR(MAX(FILTER(Elo_Player_All!$Q:$Q,Elo_Player_All!$C:$C=A15)),""""))"),"")
O16: =IFERROR(__xludf.DUMMYFUNCTION("IFERROR(INDEX(FILTER(Elo_Player_All!$Q:$Q,Elo_Player_All!$C:$C=A16),ROWS(FILTER(Elo_Player_All!$Q:$Q,Elo_Player_All!$C:$C=A16)),1),1500)"),"") | P16: =IFERROR(__xludf.DUMMYFUNCTION("IF(A16="""","""",IFERROR(SUM(QUERY(FILTER(Elo_Player_All!P:P,Elo_Player_All!C:C=A16),""LIMIT 10 OFFSET ""&MAX(0,COUNTIF(Elo_Player_All!C:C,A16)-10))),""""))"),"") | Q16: =IFERROR(__xludf.DUMMYFUNCTION("IF(A16="""","""",IFERROR(MAX(FILTER(Elo_Player_All!$Q:$Q,Elo_Player_All!$C:$C=A16)),""""))"),"")
O17: =IFERROR(__xludf.DUMMYFUNCTION("IFERROR(INDEX(FILTER(Elo_Player_All!$Q:$Q,Elo_Player_All!$C:$C=A17),ROWS(FILTER(Elo_Player_All!$Q:$Q,Elo_Player_All!$C:$C=A17)),1),1500)"),"") | P17: =IFERROR(__xludf.DUMMYFUNCTION("IF(A17="""","""",IFERROR(SUM(QUERY(FILTER(Elo_Player_All!P:P,Elo_Player_All!C:C=A17),""LIMIT 10 OFFSET ""&MAX(0,COUNTIF(Elo_Player_All!C:C,A17)-10))),""""))"),"") | Q17: =IFERROR(__xludf.DUMMYFUNCTION("IF(A17="""","""",IFERROR(MAX(FILTER(Elo_Player_All!$Q:$Q,Elo_Player_All!$C:$C=A17)),""""))"),"")
O18: =IFERROR(__xludf.DUMMYFUNCTION("IFERROR(INDEX(FILTER(Elo_Player_All!$Q:$Q,Elo_Player_All!$C:$C=A18),ROWS(FILTER(Elo_Player_All!$Q:$Q,Elo_Player_All!$C:$C=A18)),1),1500)"),"") | P18: =IFERROR(__xludf.DUMMYFUNCTION("IF(A18="""","""",IFERROR(SUM(QUERY(FILTER(Elo_Player_All!P:P,Elo_Player_All!C:C=A18),""LIMIT 10 OFFSET ""&MAX(0,COUNTIF(Elo_Player_All!C:C,A18)-10))),""""))"),"") | Q18: =IFERROR(__xludf.DUMMYFUNCTION("IF(A18="""","""",IFERROR(MAX(FILTER(Elo_Player_All!$Q:$Q,Elo_Player_All!$C:$C=A18)),""""))"),"")
O19: =IFERROR(__xludf.DUMMYFUNCTION("IFERROR(INDEX(FILTER(Elo_Player_All!$Q:$Q,Elo_Player_All!$C:$C=A19),ROWS(FILTER(Elo_Player_All!$Q:$Q,Elo_Player_All!$C:$C=A19)),1),1500)"),"") | P19: =IFERROR(__xludf.DUMMYFUNCTION("IF(A19="""","""",IFERROR(SUM(QUERY(FILTER(Elo_Player_All!P:P,Elo_Player_All!C:C=A19),""LIMIT 10 OFFSET ""&MAX(0,COUNTIF(Elo_Player_All!C:C,A19)-10))),""""))"),"") | Q19: =IFERROR(__xludf.DUMMYFUNCTION("IF(A19="""","""",IFERROR(MAX(FILTER(Elo_Player_All!$Q:$Q,Elo_Player_All!$C:$C=A19)),""""))"),"")
O20: =IFERROR(__xludf.DUMMYFUNCTION("IFERROR(INDEX(FILTER(Elo_Player_All!$Q:$Q,Elo_Player_All!$C:$C=A20),ROWS(FILTER(Elo_Player_All!$Q:$Q,Elo_Player_All!$C:$C=A20)),1),1500)"),"") | P20: =IFERROR(__xludf.DUMMYFUNCTION("IF(A20="""","""",IFERROR(SUM(QUERY(FILTER(Elo_Player_All!P:P,Elo_Player_All!C:C=A20),""LIMIT 10 OFFSET ""&MAX(0,COUNTIF(Elo_Player_All!C:C,A20)-10))),""""))"),"") | Q20: =IFERROR(__xludf.DUMMYFUNCTION("IF(A20="""","""",IFERROR(MAX(FILTER(Elo_Player_All!$Q:$Q,Elo_Player_All!$C:$C=A20)),""""))"),"")
O21: =IFERROR(__xludf.DUMMYFUNCTION("IFERROR(INDEX(FILTER(Elo_Player_All!$Q:$Q,Elo_Player_All!$C:$C=A21),ROWS(FILTER(Elo_Player_All!$Q:$Q,Elo_Player_All!$C:$C=A21)),1),1500)"),"") | P21: =IFERROR(__xludf.DUMMYFUNCTION("IF(A21="""","""",IFERROR(SUM(QUERY(FILTER(Elo_Player_All!P:P,Elo_Player_All!C:C=A21),""LIMIT 10 OFFSET ""&MAX(0,COUNTIF(Elo_Player_All!C:C,A21)-10))),""""))"),"") | Q21: =IFERROR(__xludf.DUMMYFUNCTION("IF(A21="""","""",IFERROR(MAX(FILTER(Elo_Player_All!$Q:$Q,Elo_Player_All!$C:$C=A21)),""""))"),"")
O22: =IFERROR(__xludf.DUMMYFUNCTION("IFERROR(INDEX(FILTER(Elo_Player_All!$Q:$Q,Elo_Player_All!$C:$C=A22),ROWS(FILTER(Elo_Player_All!$Q:$Q,Elo_Player_All!$C:$C=A22)),1),1500)"),"") | P22: =IFERROR(__xludf.DUMMYFUNCTION("IF(A22="""","""",IFERROR(SUM(QUERY(FILTER(Elo_Player_All!P:P,Elo_Player_All!C:C=A22),""LIMIT 10 OFFSET ""&MAX(0,COUNTIF(Elo_Player_All!C:C,A22)-10))),""""))"),"") | Q22: =IFERROR(__xludf.DUMMYFUNCTION("IF(A22="""","""",IFERROR(MAX(FILTER(Elo_Player_All!$Q:$Q,Elo_Player_All!$C:$C=A22)),""""))"),"")
O23: =IFERROR(__xludf.DUMMYFUNCTION("IFERROR(INDEX(FILTER(Elo_Player_All!$Q:$Q,Elo_Player_All!$C:$C=A23),ROWS(FILTER(Elo_Player_All!$Q:$Q,Elo_Player_All!$C:$C=A23)),1),1500)"),"") | P23: =IFERROR(__xludf.DUMMYFUNCTION("IF(A23="""","""",IFERROR(SUM(QUERY(FILTER(Elo_Player_All!P:P,Elo_Player_All!C:C=A23),""LIMIT 10 OFFSET ""&MAX(0,COUNTIF(Elo_Player_All!C:C,A23)-10))),""""))"),"") | Q23: =IFERROR(__xludf.DUMMYFUNCTION("IF(A23="""","""",IFERROR(MAX(FILTER(Elo_Player_All!$Q:$Q,Elo_Player_All!$C:$C=A23)),""""))"),"")
O24: =IFERROR(__xludf.DUMMYFUNCTION("IFERROR(INDEX(FILTER(Elo_Player_All!$Q:$Q,Elo_Player_All!$C:$C=A24),ROWS(FILTER(Elo_Player_All!$Q:$Q,Elo_Player_All!$C:$C=A24)),1),1500)"),"") | P24: =IFERROR(__xludf.DUMMYFUNCTION("IF(A24="""","""",IFERROR(SUM(QUERY(FILTER(Elo_Player_All!P:P,Elo_Player_All!C:C=A24),""LIMIT 10 OFFSET ""&MAX(0,COUNTIF(Elo_Player_All!C:C,A24)-10))),""""))"),"") | Q24: =IFERROR(__xludf.DUMMYFUNCTION("IF(A24="""","""",IFERROR(MAX(FILTER(Elo_Player_All!$Q:$Q,Elo_Player_All!$C:$C=A24)),""""))"),"")
O25: =IFERROR(__xludf.DUMMYFUNCTION("IFERROR(INDEX(FILTER(Elo_Player_All!$Q:$Q,Elo_Player_All!$C:$C=A25),ROWS(FILTER(Elo_Player_All!$Q:$Q,Elo_Player_All!$C:$C=A25)),1),1500)"),"") | P25: =IFERROR(__xludf.DUMMYFUNCTION("IF(A25="""","""",IFERROR(SUM(QUERY(FILTER(Elo_Player_All!P:P,Elo_Player_All!C:C=A25),""LIMIT 10 OFFSET ""&MAX(0,COUNTIF(Elo_Player_All!C:C,A25)-10))),""""))"),"") | Q25: =IFERROR(__xludf.DUMMYFUNCTION("IF(A25="""","""",IFERROR(MAX(FILTER(Elo_Player_All!$Q:$Q,Elo_Player_All!$C:$C=A25)),""""))"),"")
O26: =IFERROR(__xludf.DUMMYFUNCTION("IFERROR(INDEX(FILTER(Elo_Player_All!$Q:$Q,Elo_Player_All!$C:$C=A26),ROWS(FILTER(Elo_Player_All!$Q:$Q,Elo_Player_All!$C:$C=A26)),1),1500)"),"") | P26: =IFERROR(__xludf.DUMMYFUNCTION("IF(A26="""","""",IFERROR(SUM(QUERY(FILTER(Elo_Player_All!P:P,Elo_Player_All!C:C=A26),""LIMIT 10 OFFSET ""&MAX(0,COUNTIF(Elo_Player_All!C:C,A26)-10))),""""))"),"") | Q26: =IFERROR(__xludf.DUMMYFUNCTION("IF(A26="""","""",IFERROR(MAX(FILTER(Elo_Player_All!$Q:$Q,Elo_Player_All!$C:$C=A26)),""""))"),"")
O27: =IFERROR(__xludf.DUMMYFUNCTION("IFERROR(INDEX(FILTER(Elo_Player_All!$Q:$Q,Elo_Player_All!$C:$C=A27),ROWS(FILTER(Elo_Player_All!$Q:$Q,Elo_Player_All!$C:$C=A27)),1),1500)"),"") | P27: =IFERROR(__xludf.DUMMYFUNCTION("IF(A27="""","""",IFERROR(SUM(QUERY(FILTER(Elo_Player_All!P:P,Elo_Player_All!C:C=A27),""LIMIT 10 OFFSET ""&MAX(0,COUNTIF(Elo_Player_All!C:C,A27)-10))),""""))"),"") | Q27: =IFERROR(__xludf.DUMMYFUNCTION("IF(A27="""","""",IFERROR(MAX(FILTER(Elo_Player_All!$Q:$Q,Elo_Player_All!$C:$C=A27)),""""))"),"")
O28: =IFERROR(__xludf.DUMMYFUNCTION("IFERROR(INDEX(FILTER(Elo_Player_All!$Q:$Q,Elo_Player_All!$C:$C=A28),ROWS(FILTER(Elo_Player_All!$Q:$Q,Elo_Player_All!$C:$C=A28)),1),1500)"),"") | P28: =IFERROR(__xludf.DUMMYFUNCTION("IF(A28="""","""",IFERROR(SUM(QUERY(FILTER(Elo_Player_All!P:P,Elo_Player_All!C:C=A28),""LIMIT 10 OFFSET ""&MAX(0,COUNTIF(Elo_Player_All!C:C,A28)-10))),""""))"),"") | Q28: =IFERROR(__xludf.DUMMYFUNCTION("IF(A28="""","""",IFERROR(MAX(FILTER(Elo_Player_All!$Q:$Q,Elo_Player_All!$C:$C=A28)),""""))"),"")
O29: =IFERROR(__xludf.DUMMYFUNCTION("IFERROR(INDEX(FILTER(Elo_Player_All!$Q:$Q,Elo_Player_All!$C:$C=A29),ROWS(FILTER(Elo_Player_All!$Q:$Q,Elo_Player_All!$C:$C=A29)),1),1500)"),"") | P29: =IFERROR(__xludf.DUMMYFUNCTION("IF(A29="""","""",IFERROR(SUM(QUERY(FILTER(Elo_Player_All!P:P,Elo_Player_All!C:C=A29),""LIMIT 10 OFFSET ""&MAX(0,COUNTIF(Elo_Player_All!C:C,A29)-10))),""""))"),"") | Q29: =IFERROR(__xludf.DUMMYFUNCTION("IF(A29="""","""",IFERROR(MAX(FILTER(Elo_Player_All!$Q:$Q,Elo_Player_All!$C:$C=A29)),""""))"),"")
O30: =IFERROR(__xludf.DUMMYFUNCTION("IFERROR(INDEX(FILTER(Elo_Player_All!$Q:$Q,Elo_Player_All!$C:$C=A30),ROWS(FILTER(Elo_Player_All!$Q:$Q,Elo_Player_All!$C:$C=A30)),1),1500)"),"") | P30: =IFERROR(__xludf.DUMMYFUNCTION("IF(A30="""","""",IFERROR(SUM(QUERY(FILTER(Elo_Player_All!P:P,Elo_Player_All!C:C=A30),""LIMIT 10 OFFSET ""&MAX(0,COUNTIF(Elo_Player_All!C:C,A30)-10))),""""))"),"")
O31: =IFERROR(__xludf.DUMMYFUNCTION("IFERROR(INDEX(FILTER(Elo_Player_All!$Q:$Q,Elo_Player_All!$C:$C=A31),ROWS(FILTER(Elo_Player_All!$Q:$Q,Elo_Player_All!$C:$C=A31)),1),1500)"),"") | P31: =IFERROR(__xludf.DUMMYFUNCTION("IF(A31="""","""",IFERROR(SUM(QUERY(FILTER(Elo_Player_All!P:P,Elo_Player_All!C:C=A31),""LIMIT 10 OFFSET ""&MAX(0,COUNTIF(Elo_Player_All!C:C,A31)-10))),""""))"),"") | Q31: =IFERROR(__xludf.DUMMYFUNCTION("IF(A31="""","""",IFERROR(MAX(FILTER(Elo_Player_All!$Q:$Q,Elo_Player_All!$C:$C=A31)),""""))"),"")
O32: =IFERROR(__xludf.DUMMYFUNCTION("IFERROR(INDEX(FILTER(Elo_Player_All!$Q:$Q,Elo_Player_All!$C:$C=A32),ROWS(FILTER(Elo_Player_All!$Q:$Q,Elo_Player_All!$C:$C=A32)),1),1500)"),"") | P32: =IFERROR(__xludf.DUMMYFUNCTION("IF(A32="""","""",IFERROR(SUM(QUERY(FILTER(Elo_Player_All!P:P,Elo_Player_All!C:C=A32),""LIMIT 10 OFFSET ""&MAX(0,COUNTIF(Elo_Player_All!C:C,A32)-10))),""""))"),"") | Q32: =IFERROR(__xludf.DUMMYFUNCTION("IF(A32="""","""",IFERROR(MAX(FILTER(Elo_Player_All!$Q:$Q,Elo_Player_All!$C:$C=A32)),""""))"),"")
O33: =IFERROR(__xludf.DUMMYFUNCTION("IFERROR(INDEX(FILTER(Elo_Player_All!$Q:$Q,Elo_Player_All!$C:$C=A33),ROWS(FILTER(Elo_Player_All!$Q:$Q,Elo_Player_All!$C:$C=A33)),1),1500)"),"") | P33: =IFERROR(__xludf.DUMMYFUNCTION("IF(A33="""","""",IFERROR(SUM(QUERY(FILTER(Elo_Player_All!P:P,Elo_Player_All!C:C=A33),""LIMIT 10 OFFSET ""&MAX(0,COUNTIF(Elo_Player_All!C:C,A33)-10))),""""))"),"") | Q33: =IFERROR(__xludf.DUMMYFUNCTION("IF(A33="""","""",IFERROR(MAX(FILTER(Elo_Player_All!$Q:$Q,Elo_Player_All!$C:$C=A33)),""""))"),"")
O34: =IFERROR(__xludf.DUMMYFUNCTION("IFERROR(INDEX(FILTER(Elo_Player_All!$Q:$Q,Elo_Player_All!$C:$C=A34),ROWS(FILTER(Elo_Player_All!$Q:$Q,Elo_Player_All!$C:$C=A34)),1),1500)"),"") | P34: =IFERROR(__xludf.DUMMYFUNCTION("IF(A34="""","""",IFERROR(SUM(QUERY(FILTER(Elo_Player_All!P:P,Elo_Player_All!C:C=A34),""LIMIT 10 OFFSET ""&MAX(0,COUNTIF(Elo_Player_All!C:C,A34)-10))),""""))"),"") | Q34: =IFERROR(__xludf.DUMMYFUNCTION("IF(A34="""","""",IFERROR(MAX(FILTER(Elo_Player_All!$Q:$Q,Elo_Player_All!$C:$C=A34)),""""))"),"")
O35: =IFERROR(__xludf.DUMMYFUNCTION("IFERROR(INDEX(FILTER(Elo_Player_All!$Q:$Q,Elo_Player_All!$C:$C=A35),ROWS(FILTER(Elo_Player_All!$Q:$Q,Elo_Player_All!$C:$C=A35)),1),1500)"),"") | P35: =IFERROR(__xludf.DUMMYFUNCTION("IF(A35="""","""",IFERROR(SUM(QUERY(FILTER(Elo_Player_All!P:P,Elo_Player_All!C:C=A35),""LIMIT 10 OFFSET ""&MAX(0,COUNTIF(Elo_Player_All!C:C,A35)-10))),""""))"),"") | Q35: =IFERROR(__xludf.DUMMYFUNCTION("IF(A35="""","""",IFERROR(MAX(FILTER(Elo_Player_All!$Q:$Q,Elo_Player_All!$C:$C=A35)),""""))"),"")
O36: =IFERROR(__xludf.DUMMYFUNCTION("IFERROR(INDEX(FILTER(Elo_Player_All!$Q:$Q,Elo_Player_All!$C:$C=A36),ROWS(FILTER(Elo_Player_All!$Q:$Q,Elo_Player_All!$C:$C=A36)),1),1500)"),"") | Q36: =IFERROR(__xludf.DUMMYFUNCTION("IF(A36="""","""",IFERROR(MAX(FILTER(Elo_Player_All!$Q:$Q,Elo_Player_All!$C:$C=A36)),""""))"),"")
O37: =IFERROR(__xludf.DUMMYFUNCTION("IFERROR(INDEX(FILTER(Elo_Player_All!$Q:$Q,Elo_Player_All!$C:$C=A37),ROWS(FILTER(Elo_Player_All!$Q:$Q,Elo_Player_All!$C:$C=A37)),1),1500)"),"")
O38: =IFERROR(__xludf.DUMMYFUNCTION("IFERROR(INDEX(FILTER(Elo_Player_All!$Q:$Q,Elo_Player_All!$C:$C=A38),ROWS(FILTER(Elo_Player_All!$Q:$Q,Elo_Player_All!$C:$C=A38)),1),1500)"),"")
O39: =IFERROR(__xludf.DUMMYFUNCTION("IFERROR(INDEX(FILTER(Elo_Player_All!$Q:$Q,Elo_Player_All!$C:$C=A39),ROWS(FILTER(Elo_Player_All!$Q:$Q,Elo_Player_All!$C:$C=A39)),1),1500)"),"")
O40: =IFERROR(__xludf.DUMMYFUNCTION("IFERROR(INDEX(FILTER(Elo_Player_All!$Q:$Q,Elo_Player_All!$C:$C=A40),ROWS(FILTER(Elo_Player_All!$Q:$Q,Elo_Player_All!$C:$C=A40)),1),1500)"),"")
...

Sheet Player_Stats_All_Time_2v2
A1: player_name | B1: games_played | C1: wins | D1: losses | E1: winrate | F1: total_goals | G1: avg_goals | H1: total_assists | I1: avg_assists | J1: total_damage | K1: avg_damage | L1: total_score | M1: avg_score | N1: avg_dps
A2: =IFERROR(__xludf.DUMMYFUNCTION("SORT( UNIQUE( FILTER( Raw!L2:L1000, Raw!L2:L1000<>"""", Raw!F2:F1000=""2v2"" ) ) ) "),"Aferdita") -> Aferdita | B2: {=IF(A2:A1000="", , COUNTIFS( Raw!L:L, A2:A1000, Raw!F:F, "2v2" ) )} -> 8 | C2: {=IF(A2:A1000="", , COUNTIFS( Raw!L:L, A2:A1000, Raw!I:I, "win", Raw!F:F, "2v2" ) )} -> 3 | D2: {=IF(A2:A1000="", , COUNTIFS( Raw!L:L, A2:A1000, Raw!I:I, "loss", Raw!F:F, "2v2" ) )} -> 5 | E2: {=IF(A2:A1000="", , IF(B2:B1000=0, , C2:C1000 / B2:B1000) )} -> 0.375 | F2: =IFERROR(__xludf.DUMMYFUNCTION("ARRAYFORMULA( MAP( A2:A1000, LAMBDA(id, IF(id="""",, SUM( FILTER( N(Raw!M:M), Raw!L:L = id, TRIM(SUBSTITUTE(Raw!F:F, CHAR(160), "" "")) = ""2v2"" ) ) ) ) ) ) "),15.0) -> 15 | G2: {=IF(A2:A1000="", , IF(B2:B1000=0, , F2:F1000 / B2:B1000) )} -> 1.875 | H2: =IFERROR(__xludf.DUMMYFUNCTION("ARRAYFORMULA( MAP( A2:A1000, LAMBDA(id, IF(id="""",, SUM( FILTER( N(Raw!O:O), Raw!L:L = id, TRIM(SUBSTITUTE(Raw!F:F, CHAR(160), "" "")) = ""2v2"" ) ) ) ) ) ) "),3.0) -> 3 | I2: {=IF(A2:A1000="", , IF(B2:B1000=0, , H2:H1000 / B2:B1000) )} -> 0.375 | J2: =IFERROR(__xludf.DUMMYFUNCTION("ARRAYFORMULA( MAP( A2:A1000, LAMBDA(id, IF(id="""",, SUM( FILTER( N(Raw!P:P), Raw!L:L = id, TRIM(SUBSTITUTE(Raw!F:F, CHAR(160), "" "")) = ""2v2"" ) ) ) ) ) ) "),12694.0) -> 12694 | K2: {=IF(A2:A1000="", , IF(B2:B1000=0, , J2:J1000 / B2:B1000) )} -> 1586.75 | L2: =IFERROR(__xludf.DUMMYFUNCTION("ARRAYFORMULA( MAP( A2:A1000, LAMBDA(id, IF(id="""",, SUM( FILTER( N(Raw!Q:Q), Raw!L:L = id, TRIM(SUBSTITUTE(Raw!F:F, CHAR(160), "" "")) = ""2v2"" ) ) ) ) ) ) "),727.0) -> 727 | M2: {=IF(A2:A1000="", , IF(B2:B1000=0, , L2:L1000 / B2:B1000) )} -> 90.875 | N2: {=MAP( A2:A1000, LAMBDA(id, IF(id="",, IF( SUMIFS( Raw!E:E, Raw!L:L, id, Raw!F:F, "2v2" ) = 0, , SUMIFS( Raw!P:P, Raw!L:L, id, Raw!F:F, "2v2" ) / SUMIFS( Raw!E:E, Raw!L:L, id, Raw!F:F, "2v2" ) ) ) ) )} -> 1.9397922
A3: =IFERROR(__xludf.DUMMYFUNCTION("""COMPUTED_VALUE"""),"Kesny") -> Kesny | B3: 35 | C3: 11 | D3: 24 | E3: 0.31428571 | F3: =IFERROR(__xludf.DUMMYFUNCTION("""COMPUTED_VALUE"""),140.0) -> 140 | G3: 4 | H3: =IFERROR(__xludf.DUMMYFUNCTION("""COMPUTED_VALUE"""),34.0) -> 34 | I3: 0.97142857 | J3: =IFERROR(__xludf.DUMMYFUNCTION("""COMPUTED_VALUE"""),52909.0) -> 52909 | K3: 1511.6857 | L3: =IFERROR(__xludf.DUMMYFUNCTION("""COMPUTED_VALUE"""),4636.0) -> 4636 | M3: 132.45714 | N3: 1.8853651
A4: =IFERROR(__xludf.DUMMYFUNCTION("""COMPUTED_VALUE"""),"Malena") -> Malena | B4: 67 | C4: 39 | D4: 28 | E4: 0.58208955 | F4: =IFERROR(__xludf.DUMMYFUNCTION("""COMPUTED_VALUE"""),375.0) -> 375 | G4: 5.5970149 | H4: =IFERROR(__xludf.DUMMYFUNCTION("""COMPUTED_VALUE"""),20.0) -> 20 | I4: 0.29850746 | J4: =IFERROR(__xludf.DUMMYFUNCTION("""COMPUTED_VALUE"""),123485.0) -> 123485 | K4: 1843.0597 | L4: =IFERROR(__xludf.DUMMYFUNCTION("""COMPUTED_VALUE"""),9638.0) -> 9638 | M4: 143.85075 | N4: 2.4403668
A5: =IFERROR(__xludf.DUMMYFUNCTION("""COMPUTED_VALUE"""),"Nebus.") -> Nebus. | B5: 63 | C5: 39 | D5: 24 | E5: 0.61904762 | F5: =IFERROR(__xludf.DUMMYFUNCTION("""COMPUTED_VALUE"""),251.0) -> 251 | G5: 3.984127 | H5: =IFERROR(__xludf.DUMMYFUNCTION("""COMPUTED_VALUE"""),26.0) -> 26 | I5: 0.41269841 | J5: =IFERROR(__xludf.DUMMYFUNCTION("""COMPUTED_VALUE"""),138056.0) -> 138056 | K5: 2191.3651 | L5: =IFERROR(__xludf.DUMMYFUNCTION("""COMPUTED_VALUE"""),8528.0) -> 8528 | M5: 135.36508 | N5: 2.9098727
A6: =IFERROR(__xludf.DUMMYFUNCTION("""COMPUTED_VALUE"""),"Tess1509") -> Tess1509 | B6: 33 | C6: 6 | D6: 27 | E6: 0.18181818 | F6: =IFERROR(__xludf.DUMMYFUNCTION("""COMPUTED_VALUE"""),46.0) -> 46 | G6: 1.3939394 | H6: =IFERROR(__xludf.DUMMYFUNCTION("""COMPUTED_VALUE"""),7.0) -> 7 | I6: 0.21212121 | J6: =IFERROR(__xludf.DUMMYFUNCTION("""COMPUTED_VALUE"""),59288.0) -> 59288 | K6: 1796.6061 | L6: =IFERROR(__xludf.DUMMYFUNCTION("""COMPUTED_VALUE"""),2675.0) -> 2675 | M6: 81.060606 | N6: 2.5478298
A7: =IFERROR(__xludf.DUMMYFUNCTION("""COMPUTED_VALUE"""),"ZeroO") -> ZeroO | B7: 62 | C7: 36 | D7: 26 | E7: 0.58064516 | F7: =IFERROR(__xludf.DUMMYFUNCTION("""COMPUTED_VALUE"""),322.0) -> 322 | G7: 5.1935484 | H7: =IFERROR(__xludf.DUMMYFUNCTION("""COMPUTED_VALUE"""),27.0) -> 27 | I7: 0.43548387 | J7: =IFERROR(__xludf.DUMMYFUNCTION("""COMPUTED_VALUE"""),108680.0) -> 108680 | K7: 1752.9032 | L7: =IFERROR(__xludf.DUMMYFUNCTION("""COMPUTED_VALUE"""),8517.0) -> 8517 | M7: 137.37097 | N7: 2.3381094

Sheet Player_Stats_All_Time_3v3
A1: player_name | B1: games_played | C1: wins | D1: losses | E1: winrate | F1: total_goals | G1: avg_goals | H1: total_assists | I1: avg_assists | J1: total_damage | K1: avg_damage | L1: total_score | M1: avg_score | N1: avg_dps
A2: =IFERROR(__xludf.DUMMYFUNCTION("SORT( UNIQUE( FILTER( Raw!L2:L1000, Raw!L2:L1000<>"""", Raw!F2:F1000=""3v3"" ) ) ) "),"Aferdita") -> Aferdita | B2: {=IF(A2:A1000="", , COUNTIFS( Raw!L:L, A2:A1000, Raw!F:F, "3v3" ) )} -> 21 | C2: {=IF(A2:A1000="", , COUNTIFS( Raw!L:L, A2:A1000, Raw!I:I, "win", Raw!F:F, "3v3" ) )} -> 10 | D2: {=IF(A2:A1000="", , COUNTIFS( Raw!L:L, A2:A1000, Raw!I:I, "loss", Raw!F:F, "3v3" ) )} -> 11 | E2: {=IF(A2:A1000="", , IF(B2:B1000=0, , C2:C1000 / B2:B1000) )} -> 0.47619048 | F2: =IFERROR(__xludf.DUMMYFUNCTION("ARRAYFORMULA( MAP( A2:A1000, LAMBDA(id, IF(id="""",, SUM( FILTER( N(Raw!M:M), Raw!L:L = id, TRIM(SUBSTITUTE(Raw!F:F, CHAR(160), "" "")) = ""3v3"" ) ) ) ) ) ) "),39.0) -> 39 | G2: {=IF(A2:A1000="", , IF(B2:B1000=0, , F2:F1000 / B2:B1000) )} -> 1.8571429 | H2: =IFERROR(__xludf.DUMMYFUNCTION("ARRAYFORMULA( MAP( A2:A1000, LAMBDA(id, IF(id="""",, SUM( FILTER( N(Raw!O:O), Raw!L:L = id, TRIM(SUBSTITUTE(Raw!F:F, CHAR(160), "" "")) = ""3v3"" ) ) ) ) ) ) "),7.0) -> 7 | I2: {=IF(A2:A1000="", , IF(B2:B1000=0, , H2:H1000 / B2:B1000) )} -> 0.33333333 | J2: =IFERROR(__xludf.DUMMYFUNCTION("ARRAYFORMULA( MAP( A2:A1000, LAMBDA(id, IF(id="""",, SUM( FILTER( N(Raw!P:P), Raw!L:L = id, TRIM(SUBSTITUTE(Raw!F:F, CHAR(160), "" "")) = ""3v3"" ) ) ) ) ) ) "),33684.0) -> 33684 | K2: {=IF(A2:A1000="", , IF(B2:B1000=0, , J2:J1000 / B2:B1000) )} -> 1604 | L2: =IFERROR(__xludf.DUMMYFUNCTION("ARRAYFORMULA( MAP( A2:A1000, LAMBDA(id, IF(id="""",, SUM( FILTER( N(Raw!Q:Q), Raw!L:L = id, TRIM(SUBSTITUTE(Raw!F:F, CHAR(160), "" "")) = ""3v3"" ) ) ) ) ) ) "),2028.0) -> 2028 | M2: {=IF(A2:A1000="", , IF(B2:B1000=0, , L2:L1000 / B2:B1000) )} -> 96.571429 | N2: {=MAP( A2:A1000, LAMBDA(id, IF(id="",, IF( SUMIFS( Raw!E:E, Raw!L:L, id, Raw!F:F, "3v3" ) = 0, , SUMIFS( Raw!P:P, Raw!L:L, id, Raw!F:F, "3v3" ) / SUMIFS( Raw!E:E, Raw!L:L, id, Raw!F:F, "3v3" ) ) ) ) )} -> 1.5479779
A3: =IFERROR(__xludf.DUMMYFUNCTION("""COMPUTED_VALUE"""),"Anbuu") -> Anbuu | B3: 12 | C3: 8 | D3: 4 | E3: 0.66666667 | F3: =IFERROR(__xludf.DUMMYFUNCTION("""COMPUTED_VALUE"""),6.0) -> 6 | G3: 0.5 | H3: =IFERROR(__xludf.DUMMYFUNCTION("""COMPUTED_VALUE"""),4.0) -> 4 | I3: 0.33333333 | J3: =IFERROR(__xludf.DUMMYFUNCTION("""COMPUTED_VALUE"""),43928.0) -> 43928 | K3: 3660.6667 | L3: =IFERROR(__xludf.DUMMYFUNCTION("""COMPUTED_VALUE"""),1634.0) -> 1634 | M3: 136.16667 | N3: 3.4711972
A4: =IFERROR(__xludf.DUMMYFUNCTION("""COMPUTED_VALUE"""),"Kesny") -> Kesny | B4: 30 | C4: 12 | D4: 18 | E4: 0.4 | F4: =IFERROR(__xludf.DUMMYFUNCTION("""COMPUTED_VALUE"""),84.0) -> 84 | G4: 2.8 | H4: =IFERROR(__xludf.DUMMYFUNCTION("""COMPUTED_VALUE"""),30.0) -> 30 | I4: 1 | J4: =IFERROR(__xludf.DUMMYFUNCTION("""COMPUTED_VALUE"""),64489.0) -> 64489 | K4: 2149.6333 | L4: =IFERROR(__xludf.DUMMYFUNCTION("""COMPUTED_VALUE"""),4435.0) -> 4435 | M4: 147.83333 | N4: 2.086415
A5: =IFERROR(__xludf.DUMMYFUNCTION("""COMPUTED_VALUE"""),"Malena") -> Malena | B5: 30 | C5: 13 | D5: 17 | E5: 0.43333333 | F5: =IFERROR(__xludf.DUMMYFUNCTION("""COMPUTED_VALUE"""),140.0) -> 140 | G5: 4.6666667 | H5: =IFERROR(__xludf.DUMMYFUNCTION("""COMPUTED_VALUE"""),13.0) -> 13 | I5: 0.43333333 | J5: =IFERROR(__xludf.DUMMYFUNCTION("""COMPUTED_VALUE"""),88068.0) -> 88068 | K5: 2935.6 | L5: =IFERROR(__xludf.DUMMYFUNCTION("""COMPUTED_VALUE"""),5428.0) -> 5428 | M5: 180.93333 | N5: 2.8492672
A6: =IFERROR(__xludf.DUMMYFUNCTION("""COMPUTED_VALUE"""),"Nebus.") -> Nebus. | B6: 30 | C6: 22 | D6: 8 | E6: 0.73333333 | F6: =IFERROR(__xludf.DUMMYFUNCTION("""COMPUTED_VALUE"""),77.0) -> 77 | G6: 2.5666667 | H6: =IFERROR(__xludf.DUMMYFUNCTION("""COMPUTED_VALUE"""),11.0) -> 11 | I6: 0.36666667 | J6: =IFERROR(__xludf.DUMMYFUNCTION("""COMPUTED_VALUE"""),95631.0) -> 95631 | K6: 3187.7 | L6: =IFERROR(__xludf.DUMMYFUNCTION("""COMPUTED_VALUE"""),4741.0) -> 4741 | M6: 158.03333 | N6: 3.0939532
A7: =IFERROR(__xludf.DUMMYFUNCTION("""COMPUTED_VALUE"""),"Tess1509") -> Tess1509 | B7: 22 | C7: 6 | D7: 16 | E7: 0.27272727 | F7: =IFERROR(__xludf.DUMMYFUNCTION("""COMPUTED_VALUE"""),13.0) -> 13 | G7: 0.59090909 | H7: =IFERROR(__xludf.DUMMYFUNCTION("""COMPUTED_VALUE"""),15.0) -> 15 | I7: 0.68181818 | J7: =IFERROR(__xludf.DUMMYFUNCTION("""COMPUTED_VALUE"""),56065.0) -> 56065 | K7: 2548.4091 | L7: =IFERROR(__xludf.DUMMYFUNCTION("""COMPUTED_VALUE"""),2370.0) -> 2370 | M7: 107.72727 | N7: 2.4464371
A8: =IFERROR(__xludf.DUMMYFUNCTION("""COMPUTED_VALUE"""),"Troniix") -> Troniix | B8: 5 | C8: 0 | D8: 5 | E8: 0 | F8: =IFERROR(__xludf.DUMMYFUNCTION("""COMPUTED_VALUE"""),0.0) -> 0 | G8: 0 | H8: =IFERROR(__xludf.DUMMYFUNCTION("""COMPUTED_VALUE"""),2.0) -> 2 | I8: 0.4 | J8: =IFERROR(__xludf.DUMMYFUNCTION("""COMPUTED_VALUE"""),9856.0) -> 9856 | K8: 1971.2 | L8: =IFERROR(__xludf.DUMMYFUNCTION("""COMPUTED_VALUE"""),339.0) -> 339 | M8: 67.8 | N8: 2.1970575
A9: =IFERROR(__xludf.DUMMYFUNCTION("""COMPUTED_VALUE"""),"ZeroO") -> ZeroO | B9: 30 | C9: 19 | D9: 11 | E9: 0.63333333 | F9: =IFERROR(__xludf.DUMMYFUNCTION("""COMPUTED_VALUE"""),129.0) -> 129 | G9: 4.3 | H9: =IFERROR(__xludf.DUMMYFUNCTION("""COMPUTED_VALUE"""),19.0) -> 19 | I9: 0.63333333 | J9: =IFERROR(__xludf.DUMMYFUNCTION("""COMPUTED_VALUE"""),91065.0) -> 91065 | K9: 3035.5 | L9: =IFERROR(__xludf.DUMMYFUNCTION("""COMPUTED_VALUE"""),5275.0) -> 5275 | M9: 175.83333 | N9: 2.9462293

Sheet Player_Stats_S1_2v2
A1: player_name | B1: games_played | C1: wins | D1: losses | E1: winrate | F1: total_goals | G1: avg_goals | H1: total_assists | I1: avg_assists | J1: total_damage | K1: avg_damage | L1: total_score | M1: avg_score | N1: avg_dps
A2: =IFERROR(__xludf.DUMMYFUNCTION("SORT( UNIQUE( FILTER( Raw!L2:L1000, Raw!L2:L1000<>"""", Raw!C2:C1000=""Season 1"", Raw!F2:F1000=""2v2"" ) ) ) "),"Aferdita") -> Aferdita | B2: {=IF(A2:A1000="", , COUNTIFS( Raw!L:L, A2:A1000, Raw!C:C, "Season 1", Raw!F:F, "2v2" ) )} -> 3 | C2: {=IF(A2:A1000="", , COUNTIFS( Raw!L:L, A2:A1000, Raw!I:I, "win", Raw!C:C, "Season 1", Raw!F:F, "2v2" ) )} -> 1 | D2: {=IF(A2:A1000="", , COUNTIFS( Raw!L:L, A2:A1000, Raw!I:I, "loss", Raw!C:C, "Season 1", Raw!F:F, "2v2" ) )} -> 2 | E2: {=IF(A2:A1000="", , IF(B2:B1000=0, , C2:C1000 / B2:B1000) )} -> 0.33333333 | F2: =IFERROR(__xludf.DUMMYFUNCTION("ARRAYFORMULA( MAP( A2:A1000, LAMBDA(id, IF(id="""",, SUM( FILTER( N(Raw!M:M), Raw!L:L=id, TRIM(SUBSTITUTE(Raw!C:C,CHAR(160),"" ""))=""Season 1"", TRIM(SUBSTITUTE(Raw!F:F,CHAR(160),"" ""))=""2v2"" ) ) ) ) ) )"),6.0) -> 6 | G2: {=IF(A2:A1000="", , IF(B2:B1000=0, , F2:F1000 / B2:B1000) )} -> 2 | H2: =IFERROR(__xludf.DUMMYFUNCTION("ARRAYFORMULA( MAP( A2:A1000, LAMBDA(id, IF(id="""",, SUM( FILTER( N(Raw!O:O), Raw!L:L=id, TRIM(SUBSTITUTE(Raw!C:C,CHAR(160),"" ""))=""Season 1"", TRIM(SUBSTITUTE(Raw!F:F,CHAR(160),"" ""))=""2v2"" ) ) ) ) ) )"),1.0) -> 1 | I2: {=IF(A2:A1000="", , IF(B2:B1000=0, , H2:H1000 / B2:B1000) )} -> 0.33333333 | J2: =IFERROR(__xludf.DUMMYFUNCTION("ARRAYFORMULA( MAP( A2:A1000, LAMBDA(id, IF(id="""",, SUM( FILTER( N(Raw!P:P), Raw!L:L=id, TRIM(SUBSTITUTE(Raw!C:C,CHAR(160),"" ""))=""Season 1"", TRIM(SUBSTITUTE(Raw!F:F,CHAR(160),"" ""))=""2v2"" ) ) ) ) ) )"),4796.0) -> 4796 | K2: {=IF(A2:A1000="", , IF(B2:B1000=0, , J2:J1000 / B2:B1000) )} -> 1598.6667 | L2: =IFERROR(__xludf.DUMMYFUNCTION("ARRAYFORMULA( MAP( A2:A1000, LAMBDA(id, IF(id="""",, SUM( FILTER( N(Raw!Q:Q), Raw!L:L=id, TRIM(SUBSTITUTE(Raw!C:C,CHAR(160),"" ""))=""Season 1"", TRIM(SUBSTITUTE(Raw!F:F,CHAR(160),"" ""))=""2v2"" ) ) ) ) ) )"),265.0) -> 265 | M2: {=IF(A2:A1000="", , IF(B2:B1000=0, , L2:L1000 / B2:B1000) )} -> 88.333333 | N2: {=MAP( A2:A1000, LAMBDA(id, IF(id="",, IF( SUMIFS( Raw!E:E, Raw!L:L, id, Raw!C:C, "Season 1", Raw!F:F, "2v2" ) = 0, , SUMIFS( Raw!P:P, Raw!L:L, id, Raw!C:C, "Season 1", Raw!F:F, "2v2" ) / SUMIFS( Raw!E:E, Raw!L:L, id, Raw!C:C, "Season 1", Raw!F:F, "2v2" ) ) ) ) )} -> 1.977732
A3: =IFERROR(__xludf.DUMMYFUNCTION("""COMPUTED_VALUE"""),"Kesny") -> Kesny | B3: 29 | C3: 9 | D3: 20 | E3: 0.31034483 | F3: =IFERROR(__xludf.DUMMYFUNCTION("""COMPUTED_VALUE"""),114.0) -> 114 | G3: 3.9310345 | H3: =IFERROR(__xludf.DUMMYFUNCTION("""COMPUTED_VALUE"""),29.0) -> 29 | I3: 1 | J3: =IFERROR(__xludf.DUMMYFUNCTION("""COMPUTED_VALUE"""),42717.0) -> 42717 | K3: 1473 | L3: =IFERROR(__xludf.DUMMYFUNCTION("""COMPUTED_VALUE"""),3768.0) -> 3768 | M3: 129.93103 | N3: 1.8402981
A4: =IFERROR(__xludf.DUMMYFUNCTION("""COMPUTED_VALUE"""),"Malena") -> Malena | B4: 61 | C4: 36 | D4: 25 | E4: 0.59016393 | F4: =IFERROR(__xludf.DUMMYFUNCTION("""COMPUTED_VALUE"""),339.0) -> 339 | G4: 5.557377 | H4: =IFERROR(__xludf.DUMMYFUNCTION("""COMPUTED_VALUE"""),19.0) -> 19 | I4: 0.31147541 | J4: =IFERROR(__xludf.DUMMYFUNCTION("""COMPUTED_VALUE"""),108436.0) -> 108436 | K4: 1777.6393 | L4: =IFERROR(__xludf.DUMMYFUNCTION("""COMPUTED_VALUE"""),8617.0) -> 8617 | M4: 141.2623 | N4: 2.3701858
A5: =IFERROR(__xludf.DUMMYFUNCTION("""COMPUTED_VALUE"""),"Nebus.") -> Nebus. | B5: 58 | C5: 35 | D5: 23 | E5: 0.60344828 | F5: =IFERROR(__xludf.DUMMYFUNCTION("""COMPUTED_VALUE"""),222.0) -> 222 | G5: 3.8275862 | H5: =IFERROR(__xludf.DUMMYFUNCTION("""COMPUTED_VALUE"""),25.0) -> 25 | I5: 0.43103448 | J5: =IFERROR(__xludf.DUMMYFUNCTION("""COMPUTED_VALUE"""),124145.0) -> 124145 | K5: 2140.431 | L5: =IFERROR(__xludf.DUMMYFUNCTION("""COMPUTED_VALUE"""),7635.0) -> 7635 | M5: 131.63793 | N5: 2.8654357
A6: =IFERROR(__xludf.DUMMYFUNCTION("""COMPUTED_VALUE"""),"Tess1509") -> Tess1509 | B6: 32 | C6: 6 | D6: 26 | E6: 0.1875 | F6: =IFERROR(__xludf.DUMMYFUNCTION("""COMPUTED_VALUE"""),44.0) -> 44 | G6: 1.375 | H6: =IFERROR(__xludf.DUMMYFUNCTION("""COMPUTED_VALUE"""),7.0) -> 7 | I6: 0.21875 | J6: =IFERROR(__xludf.DUMMYFUNCTION("""COMPUTED_VALUE"""),57045.0) -> 57045 | K6: 1782.6562 | L6: =IFERROR(__xludf.DUMMYFUNCTION("""COMPUTED_VALUE"""),2575.0) -> 2575 | M6: 80.46875 | N6: 2.5310587
A7: =IFERROR(__xludf.DUMMYFUNCTION("""COMPUTED_VALUE"""),"ZeroO") -> ZeroO | B7: 61 | C7: 35 | D7: 26 | E7: 0.57377049 | F7: =IFERROR(__xludf.DUMMYFUNCTION("""COMPUTED_VALUE"""),317.0) -> 317 | G7: 5.1967213 | H7: =IFERROR(__xludf.DUMMYFUNCTION("""COMPUTED_VALUE"""),24.0) -> 24 | I7: 0.39344262 | J7: =IFERROR(__xludf.DUMMYFUNCTION("""COMPUTED_VALUE"""),107389.0) -> 107389 | K7: 1760.4754 | L7: =IFERROR(__xludf.DUMMYFUNCTION("""COMPUTED_VALUE"""),8385.0) -> 8385 | M7: 137.45902 | N7: 2.3473005

Sheet Player_Stats_S2_2v2
A1: player_name | B1: games_played | C1: wins | D1: losses | E1: winrate | F1: total_goals | G1: avg_goals | H1: total_assists | I1: avg_assists | J1: total_damage | K1: avg_damage | L1: total_score | M1: avg_score | N1: avg_dps
A2: =IFERROR(__xludf.DUMMYFUNCTION("SORT( UNIQUE( FILTER( Raw!L2:L1000, Raw!L2:L1000<>"""", Raw!C2:C1000=""Season 1"", Raw!F2:F1000=""2v2"" ) ) ) "),"Aferdita") -> Aferdita | B2: {=IF(A2:A1000="", , COUNTIFS( Raw!L:L, A2:A1000, Raw!C:C, "Season 2", Raw!F:F, "2v2" ) )} -> 5 | C2: {=IF(A2:A1000="", , COUNTIFS( Raw!L:L, A2:A1000, Raw!I:I, "win", Raw!C:C, "Season 2", Raw!F:F, "2v2" ) )} -> 2 | D2: {=IF(A2:A1000="", , COUNTIFS( Raw!L:L, A2:A1000, Raw!I:I, "loss", Raw!C:C, "Season 2", Raw!F:F, "2v2" ) )} -> 3 | E2: {=IF(A2:A1000="", , IF(B2:B1000=0, , C2:C1000 / B2:B1000) )} -> 0.4 | F2: =IFERROR(__xludf.DUMMYFUNCTION("ARRAYFORMULA( MAP( A2:A1000, LAMBDA(id, IF(id="""",, SUM( FILTER( N(Raw!M:M), Raw!L:L=id, TRIM(SUBSTITUTE(Raw!C:C,CHAR(160),"" ""))=""Season 2"", TRIM(SUBSTITUTE(Raw!F:F,CHAR(160),"" ""))=""2v2"" ) ) ) ) ) )"),9.0) -> 9 | G2: {=IF(A2:A1000="", , IF(B2:B1000=0, , F2:F1000 / B2:B1000) )} -> 1.8 | H2: =IFERROR(__xludf.DUMMYFUNCTION("ARRAYFORMULA( MAP( A2:A1000, LAMBDA(id, IF(id="""",, SUM( FILTER( N(Raw!O:O), Raw!L:L=id, TRIM(SUBSTITUTE(Raw!C:C,CHAR(160),"" ""))=""Season 2"", TRIM(SUBSTITUTE(Raw!F:F,CHAR(160),"" ""))=""2v2"" ) ) ) ) ) )"),2.0) -> 2 | I2: {=IF(A2:A1000="", , IF(B2:B1000=0, , H2:H1000 / B2:B1000) )} -> 0.4 | J2: =IFERROR(__xludf.DUMMYFUNCTION("ARRAYFORMULA( MAP( A2:A1000, LAMBDA(id, IF(id="""",, SUM( FILTER( N(Raw!P:P), Raw!L:L=id, TRIM(SUBSTITUTE(Raw!C:C,CHAR(160),"" ""))=""Season 2"", TRIM(SUBSTITUTE(Raw!F:F,CHAR(160),"" ""))=""2v2"" ) ) ) ) ) )"),7898.0) -> 7898 | K2: {=IF(A2:A1000="", , IF(B2:B1000=0, , J2:J1000 / B2:B1000) )} -> 1579.6 | L2: =IFERROR(__xludf.DUMMYFUNCTION("ARRAYFORMULA( MAP( A2:A1000, LAMBDA(id, IF(id="""",, SUM( FILTER( N(Raw!Q:Q), Raw!L:L=id, TRIM(SUBSTITUTE(Raw!C:C,CHAR(160),"" ""))=""Season 2"", TRIM(SUBSTITUTE(Raw!F:F,CHAR(160),"" ""))=""2v2"" ) ) ) ) ) )"),462.0) -> 462 | M2: {=IF(A2:A1000="", , IF(B2:B1000=0, , L2:L1000 / B2:B1000) )} -> 92.4 | N2: {=MAP( A2:A1000, LAMBDA(id, IF(id="",, IF( SUMIFS( Raw!E:E, Raw!L:L, id, Raw!C:C, "Season 2", Raw!F:F, "2v2" ) = 0, , SUMIFS( Raw!P:P, Raw!L:L, id, Raw!C:C, "Season 2", Raw!F:F, "2v2" ) / SUMIFS( Raw!E:E, Raw!L:L, id, Raw!C:C, "Season 2", Raw!F:F, "2v2" ) ) ) ) )} -> 1.9174557
A3: =IFERROR(__xludf.DUMMYFUNCTION("""COMPUTED_VALUE"""),"Kesny") -> Kesny | B3: 6 | C3: 2 | D3: 4 | E3: 0.33333333 | F3: =IFERROR(__xludf.DUMMYFUNCTION("""COMPUTED_VALUE"""),26.0) -> 26 | G3: 4.3333333 | H3: =IFERROR(__xludf.DUMMYFUNCTION("""COMPUTED_VALUE"""),5.0) -> 5 | I3: 0.83333333 | J3: =IFERROR(__xludf.DUMMYFUNCTION("""COMPUTED_VALUE"""),10192.0) -> 10192 | K3: 1698.6667 | L3: =IFERROR(__xludf.DUMMYFUNCTION("""COMPUTED_VALUE"""),868.0) -> 868 | M3: 144.66667 | N3: 2.1010101
A4: =IFERROR(__xludf.DUMMYFUNCTION("""COMPUTED_VALUE"""),"Malena") -> Malena | B4: 6 | C4: 3 | D4: 3 | E4: 0.5 | F4: =IFERROR(__xludf.DUMMYFUNCTION("""COMPUTED_VALUE"""),36.0) -> 36 | G4: 6 | H4: =IFERROR(__xludf.DUMMYFUNCTION("""COMPUTED_VALUE"""),1.0) -> 1 | I4: 0.16666667 | J4: =IFERROR(__xludf.DUMMYFUNCTION("""COMPUTED_VALUE"""),15049.0) -> 15049 | K4: 2508.1667 | L4: =IFERROR(__xludf.DUMMYFUNCTION("""COMPUTED_VALUE"""),1021.0) -> 1021 | M4: 170.16667 | N4: 3.102247
A5: =IFERROR(__xludf.DUMMYFUNCTION("""COMPUTED_VALUE"""),"Nebus.") -> Nebus. | B5: 5 | C5: 4 | D5: 1 | E5: 0.8 | F5: =IFERROR(__xludf.DUMMYFUNCTION("""COMPUTED_VALUE"""),29.0) -> 29 | G5: 5.8 | H5: =IFERROR(__xludf.DUMMYFUNCTION("""COMPUTED_VALUE"""),1.0) -> 1 | I5: 0.2 | J5: =IFERROR(__xludf.DUMMYFUNCTION("""COMPUTED_VALUE"""),13911.0) -> 13911 | K5: 2782.2 | L5: =IFERROR(__xludf.DUMMYFUNCTION("""COMPUTED_VALUE"""),893.0) -> 893 | M5: 178.6 | N5: 3.377276
A6: =IFERROR(__xludf.DUMMYFUNCTION("""COMPUTED_VALUE"""),"Tess1509") -> Tess1509 | B6: 1 | C6: 0 | D6: 1 | E6: 0 | F6: =IFERROR(__xludf.DUMMYFUNCTION("""COMPUTED_VALUE"""),2.0) -> 2 | G6: 2 | H6: =IFERROR(__xludf.DUMMYFUNCTION("""COMPUTED_VALUE"""),0.0) -> 0 | I6: 0 | J6: =IFERROR(__xludf.DUMMYFUNCTION("""COMPUTED_VALUE"""),2243.0) -> 2243 | K6: 2243 | L6: =IFERROR(__xludf.DUMMYFUNCTION("""COMPUTED_VALUE"""),100.0) -> 100 | M6: 100 | N6: 3.0642077
A7: =IFERROR(__xludf.DUMMYFUNCTION("""COMPUTED_VALUE"""),"ZeroO") -> ZeroO | B7: 1 | C7: 1 | D7: 0 | E7: 1 | F7: =IFERROR(__xludf.DUMMYFUNCTION("""COMPUTED_VALUE"""),5.0) -> 5 | G7: 5 | H7: =IFERROR(__xludf.DUMMYFUNCTION("""COMPUTED_VALUE"""),3.0) -> 3 | I7: 3 | J7: =IFERROR(__xludf.DUMMYFUNCTION("""COMPUTED_VALUE"""),1291.0) -> 1291 | K7: 1291 | L7: =IFERROR(__xludf.DUMMYFUNCTION("""COMPUTED_VALUE"""),132.0) -> 132 | M7: 132 | N7: 1.7636612

Sheet Player_Stats_S1_3v3
A1: player_name | B1: games_played | C1: wins | D1: losses | E1: winrate | F1: total_goals | G1: avg_goals | H1: total_assists | I1: avg_assists | J1: total_damage | K1: avg_damage | L1: total_score | M1: avg_score | N1: avg_dps
A2: =IFERROR(__xludf.DUMMYFUNCTION("SORT( UNIQUE( FILTER( Raw!L2:L1000, Raw!L2:L1000<>"""", Raw!C2:C1000=""Season 1"", Raw!F2:F1000=""3v3"" ) ) ) "),"Aferdita") -> Aferdita | B2: {=IF(A2:A1000="", , COUNTIFS( Raw!L:L, A2:A1000, Raw!C:C, "Season 1", Raw!F:F, "3v3" ) )} -> 21 | C2: {=IF(A2:A1000="", , COUNTIFS( Raw!L:L, A2:A1000, Raw!I:I, "win", Raw!C:C, "Season 1", Raw!F:F, "3v3" ) )} -> 10 | D2: {=IF(A2:A1000="", , COUNTIFS( Raw!L:L, A2:A1000, Raw!I:I, "loss", Raw!C:C, "Season 1", Raw!F:F, "3v3" ) )} -> 11 | E2: {=IF(A2:A1000="", , IF(B2:B1000=0, , C2:C1000 / B2:B1000) )} -> 0.47619048 | F2: =IFERROR(__xludf.DUMMYFUNCTION("ARRAYFORMULA( MAP( A2:A1000, LAMBDA(id, IF(id="""",, SUM( FILTER( N(Raw!M:M), Raw!L:L=id, TRIM(SUBSTITUTE(Raw!C:C,CHAR(160),"" ""))=""Season 1"", TRIM(SUBSTITUTE(Raw!F:F,CHAR(160),"" ""))=""3v3"&""" ) ) ) ) ) ) "),39.0) -> 39 | G2: {=IF(A2:A1000="", , IF(B2:B1000=0, , F2:F1000 / B2:B1000) )} -> 1.8571429 | H2: =IFERROR(__xludf.DUMMYFUNCTION("ARRAYFORMULA( MAP( A2:A1000, LAMBDA(id, IF(id="""",, SUM( FILTER( N(Raw!O:O), Raw!L:L=id, TRIM(SUBSTITUTE(Raw!C:C,CHAR(160),"" ""))=""Season 1"", TRIM(SUBSTITUTE(Raw!F:F,CHAR(160),"" ""))=""3v3"&""" ) ) ) ) ) ) "),7.0) -> 7 | I2: {=IF(A2:A1000="", , IF(B2:B1000=0, , H2:H1000 / B2:B1000) )} -> 0.33333333 | J2: =IFERROR(__xludf.DUMMYFUNCTION("ARRAYFORMULA( MAP( A2:A1000, LAMBDA(id, IF(id="""",, SUM( FILTER( N(Raw!P:P), Raw!L:L=id, TRIM(SUBSTITUTE(Raw!C:C,CHAR(160),"" ""))=""Season 1"", TRIM(SUBSTITUTE(Raw!F:F,CHAR(160),"" ""))=""3v3"&""" ) ) ) ) ) ) "),33684.0) -> 33684 | K2: {=IF(A2:A1000="", , IF(B2:B1000=0, , J2:J1000 / B2:B1000) )} -> 1604 | L2: =IFERROR(__xludf.DUMMYFUNCTION("ARRAYFORMULA( MAP( A2:A1000, LAMBDA(id, IF(id="""",, SUM( FILTER( N(Raw!Q:Q), Raw!L:L=id, TRIM(SUBSTITUTE(Raw!C:C,CHAR(160),"" ""))=""Season 1"", TRIM(SUBSTITUTE(Raw!F:F,CHAR(160),"" ""))=""3v3"&""" ) ) ) ) ) ) "),2028.0) -> 2028 | M2: {=IF(A2:A1000="", , IF(B2:B1000=0, , L2:L1000 / B2:B1000) )} -> 96.571429 | N2: {=MAP( A2:A1000, LAMBDA(id, IF(id="",, IF( SUMIFS( Raw!E:E, Raw!L:L, id, Raw!C:C, "Season 1", Raw!F:F, "3v3" ) = 0, , SUMIFS( Raw!P:P, Raw!L:L, id, Raw!C:C, "Season 1", Raw!F:F, "3v3" ) / SUMIFS( Raw!E:E, Raw!L:L, id, Raw!C:C, "Season 1", Raw!F:F, "3v3" ) ) ) ) )} -> 1.5479779
A3: =IFERROR(__xludf.DUMMYFUNCTION("""COMPUTED_VALUE"""),"Anbuu") -> Anbuu | B3: 12 | C3: 8 | D3: 4 | E3: 0.66666667 | F3: =IFERROR(__xludf.DUMMYFUNCTION("""COMPUTED_VALUE"""),6.0) -> 6 | G3: 0.5 | H3: =IFERROR(__xludf.DUMMYFUNCTION("""COMPUTED_VALUE"""),4.0) -> 4 | I3: 0.33333333 | J3: =IFERROR(__xludf.DUMMYFUNCTION("""COMPUTED_VALUE"""),43928.0) -> 43928 | K3: 3660.6667 | L3: =IFERROR(__xludf.DUMMYFUNCTION("""COMPUTED_VALUE"""),1634.0) -> 1634 | M3: 136.16667 | N3: 3.4711972
A4: =IFERROR(__xludf.DUMMYFUNCTION("""COMPUTED_VALUE"""),"Kesny") -> Kesny | B4: 30 | C4: 12 | D4: 18 | E4: 0.4 | F4: =IFERROR(__xludf.DUMMYFUNCTION("""COMPUTED_VALUE"""),84.0) -> 84 | G4: 2.8 | H4: =IFERROR(__xludf.DUMMYFUNCTION("""COMPUTED_VALUE"""),30.0) -> 30 | I4: 1 | J4: =IFERROR(__xludf.DUMMYFUNCTION("""COMPUTED_VALUE"""),64489.0) -> 64489 | K4: 2149.6333 | L4: =IFERROR(__xludf.DUMMYFUNCTION("""COMPUTED_VALUE"""),4435.0) -> 4435 | M4: 147.83333 | N4: 2.086415
A5: =IFERROR(__xludf.DUMMYFUNCTION("""COMPUTED_VALUE"""),"Malena") -> Malena | B5: 30 | C5: 13 | D5: 17 | E5: 0.43333333 | F5: =IFERROR(__xludf.DUMMYFUNCTION("""COMPUTED_VALUE"""),140.0) -> 140 | G5: 4.6666667 | H5: =IFERROR(__xludf.DUMMYFUNCTION("""COMPUTED_VALUE"""),13.0) -> 13 | I5: 0.43333333 | J5: =IFERROR(__xludf.DUMMYFUNCTION("""COMPUTED_VALUE"""),88068.0) -> 88068 | K5: 2935.6 | L5: =IFERROR(__xludf.DUMMYFUNCTION("""COMPUTED_VALUE"""),5428.0) -> 5428 | M5: 180.93333 | N5: 2.8492672
A6: =IFERROR(__xludf.DUMMYFUNCTION("""COMPUTED_VALUE"""),"Nebus.") -> Nebus. | B6: 30 | C6: 22 | D6: 8 | E6: 0.73333333 | F6: =IFERROR(__xludf.DUMMYFUNCTION("""COMPUTED_VALUE"""),77.0) -> 77 | G6: 2.5666667 | H6: =IFERROR(__xludf.DUMMYFUNCTION("""COMPUTED_VALUE"""),11.0) -> 11 | I6: 0.36666667 | J6: =IFERROR(__xludf.DUMMYFUNCTION("""COMPUTED_VALUE"""),95631.0) -> 95631 | K6: 3187.7 | L6: =IFERROR(__xludf.DUMMYFUNCTION("""COMPUTED_VALUE"""),4741.0) -> 4741 | M6: 158.03333 | N6: 3.0939532
A7: =IFERROR(__xludf.DUMMYFUNCTION("""COMPUTED_VALUE"""),"Tess1509") -> Tess1509 | B7: 22 | C7: 6 | D7: 16 | E7: 0.27272727 | F7: =IFERROR(__xludf.DUMMYFUNCTION("""COMPUTED_VALUE"""),13.0) -> 13 | G7: 0.59090909 | H7: =IFERROR(__xludf.DUMMYFUNCTION("""COMPUTED_VALUE"""),15.0) -> 15 | I7: 0.68181818 | J7: =IFERROR(__xludf.DUMMYFUNCTION("""COMPUTED_VALUE"""),56065.0) -> 56065 | K7: 2548.4091 | L7: =IFERROR(__xludf.DUMMYFUNCTION("""COMPUTED_VALUE"""),2370.0) -> 2370 | M7: 107.72727 | N7: 2.4464371
A8: =IFERROR(__xludf.DUMMYFUNCTION("""COMPUTED_VALUE"""),"Troniix") -> Troniix | B8: 5 | C8: 0 | D8: 5 | E8: 0 | F8: =IFERROR(__xludf.DUMMYFUNCTION("""COMPUTED_VALUE"""),0.0) -> 0 | G8: 0 | H8: =IFERROR(__xludf.DUMMYFUNCTION("""COMPUTED_VALUE"""),2.0) -> 2 | I8: 0.4 | J8: =IFERROR(__xludf.DUMMYFUNCTION("""COMPUTED_VALUE"""),9856.0) -> 9856 | K8: 1971.2 | L8: =IFERROR(__xludf.DUMMYFUNCTION("""COMPUTED_VALUE"""),339.0) -> 339 | M8: 67.8 | N8: 2.1970575
A9: =IFERROR(__xludf.DUMMYFUNCTION("""COMPUTED_VALUE"""),"ZeroO") -> ZeroO | B9: 30 | C9: 19 | D9: 11 | E9: 0.63333333 | F9: =IFERROR(__xludf.DUMMYFUNCTION("""COMPUTED_VALUE"""),129.0) -> 129 | G9: 4.3 | H9: =IFERROR(__xludf.DUMMYFUNCTION("""COMPUTED_VALUE"""),19.0) -> 19 | I9: 0.63333333 | J9: =IFERROR(__xludf.DUMMYFUNCTION("""COMPUTED_VALUE"""),91065.0) -> 91065 | K9: 3035.5 | L9: =IFERROR(__xludf.DUMMYFUNCTION("""COMPUTED_VALUE"""),5275.0) -> 5275 | M9: 175.83333 | N9: 2.9462293

Sheet Player_Stats_S2_3v3
A1: player_name | B1: games_played | C1: wins | D1: losses | E1: winrate | F1: total_goals | G1: avg_goals | H1: total_assists | I1: avg_assists | J1: total_damage | K1: avg_damage | L1: total_score | M1: avg_score | N1: avg_dps
A2: =IFERROR(__xludf.DUMMYFUNCTION("SORT( UNIQUE( FILTER( Raw!L2:L1000, Raw!L2:L1000<>"""", Raw!C2:C1000=""Season 1"", Raw!F2:F1000=""3v3"" ) ) ) "),"Aferdita") -> Aferdita | B2: {=IF(A2:A1000="", , COUNTIFS( Raw!L:L, A2:A1000, Raw!C:C, "Season 2", Raw!F:F, "3v3" ) )} -> 0 | C2: {=IF(A2:A1000="", , COUNTIFS( Raw!L:L, A2:A1000, Raw!I:I, "win", Raw!C:C, "Season 2", Raw!F:F, "3v3" ) )} -> 0 | D2: {=IF(A2:A1000="", , COUNTIFS( Raw!L:L, A2:A1000, Raw!I:I, "loss", Raw!C:C, "Season 2", Raw!F:F, "3v3" ) )} -> 0 | E2: {=IF(A2:A1000="", , IF(B2:B1000=0, , C2:C1000 / B2:B1000) )} | F2: =IFERROR(__xludf.DUMMYFUNCTION("ARRAYFORMULA( MAP( A2:A1000, LAMBDA(id, IF(id="""",, SUM( FILTER( N(Raw!M:M), Raw!L:L=id, TRIM(SUBSTITUTE(Raw!C:C,CHAR(160),"" ""))=""Season 2"", TRIM(SUBSTITUTE(Raw!F:F,CHAR(160),"" ""))=""3v3"&""" ) ) ) ) ) ) "),"#N/A") -> #N/A | G2: {=IF(A2:A1000="", , IF(B2:B1000=0, , F2:F1000 / B2:B1000) )} | H2: =IFERROR(__xludf.DUMMYFUNCTION("ARRAYFORMULA( MAP( A2:A1000, LAMBDA(id, IF(id="""",, SUM( FILTER( N(Raw!O:O), Raw!L:L=id, TRIM(SUBSTITUTE(Raw!C:C,CHAR(160),"" ""))=""Season 2"", TRIM(SUBSTITUTE(Raw!F:F,CHAR(160),"" ""))=""3v3"&""" ) ) ) ) ) ) "),"#N/A") -> #N/A | I2: {=IF(A2:A1000="", , IF(B2:B1000=0, , H2:H1000 / B2:B1000) )} | J2: =IFERROR(__xludf.DUMMYFUNCTION("ARRAYFORMULA( MAP( A2:A1000, LAMBDA(id, IF(id="""",, SUM( FILTER( N(Raw!P:P), Raw!L:L=id, TRIM(SUBSTITUTE(Raw!C:C,CHAR(160),"" ""))=""Season 2"", TRIM(SUBSTITUTE(Raw!F:F,CHAR(160),"" ""))=""3v3"&""" ) ) ) ) ) ) "),"#N/A") -> #N/A | K2: {=IF(A2:A1000="", , IF(B2:B1000=0, , J2:J1000 / B2:B1000) )} | L2: =IFERROR(__xludf.DUMMYFUNCTION("ARRAYFORMULA( MAP( A2:A1000, LAMBDA(id, IF(id="""",, SUM( FILTER( N(Raw!Q:Q), Raw!L:L=id, TRIM(SUBSTITUTE(Raw!C:C,CHAR(160),"" ""))=""Season 2"", TRIM(SUBSTITUTE(Raw!F:F,CHAR(160),"" ""))=""3v3"&""" ) ) ) ) ) ) "),"#N/A") -> #N/A | M2: {=IF(A2:A1000="", , IF(B2:B1000=0, , L2:L1000 / B2:B1000) )} | N2: {=MAP( A2:A1000, LAMBDA(id, IF(id="",, IF( SUMIFS( Raw!E:E, Raw!L:L, id, Raw!C:C, "Season 2", Raw!F:F, "3v3" ) = 0, , SUMIFS( Raw!P:P, Raw!L:L, id, Raw!C:C, "Season 2", Raw!F:F, "3v3" ) / SUMIFS( Raw!E:E, Raw!L:L, id, Raw!C:C, "Season 2", Raw!F:F, "3v3" ) ) ) ) )}
A3: =IFERROR(__xludf.DUMMYFUNCTION("""COMPUTED_VALUE"""),"Anbuu") -> Anbuu | B3: 0 | C3: 0 | D3: 0 | F3: =IFERROR(__xludf.DUMMYFUNCTION("""COMPUTED_VALUE"""),"#N/A") -> #N/A | H3: =IFERROR(__xludf.DUMMYFUNCTION("""COMPUTED_VALUE"""),"#N/A") -> #N/A | J3: =IFERROR(__xludf.DUMMYFUNCTION("""COMPUTED_VALUE"""),"#N/A") -> #N/A | L3: =IFERROR(__xludf.DUMMYFUNCTION("""COMPUTED_VALUE"""),"#N/A") -> #N/A
A4: =IFERROR(__xludf.DUMMYFUNCTION("""COMPUTED_VALUE"""),"Kesny") -> Kesny | B4: 0 | C4: 0 | D4: 0 | F4: =IFERROR(__xludf.DUMMYFUNCTION("""COMPUTED_VALUE"""),"#N/A") -> #N/A | H4: =IFERROR(__xludf.DUMMYFUNCTION("""COMPUTED_VALUE"""),"#N/A") -> #N/A | J4: =IFERROR(__xludf.DUMMYFUNCTION("""COMPUTED_VALUE"""),"#N/A") -> #N/A | L4: =IFERROR(__xludf.DUMMYFUNCTION("""COMPUTED_VALUE"""),"#N/A") -> #N/A
A5: =IFERROR(__xludf.DUMMYFUNCTION("""COMPUTED_VALUE"""),"Malena") -> Malena | B5: 0 | C5: 0 | D5: 0 | F5: =IFERROR(__xludf.DUMMYFUNCTION("""COMPUTED_VALUE"""),"#N/A") -> #N/A | H5: =IFERROR(__xludf.DUMMYFUNCTION("""COMPUTED_VALUE"""),"#N/A") -> #N/A | J5: =IFERROR(__xludf.DUMMYFUNCTION("""COMPUTED_VALUE"""),"#N/A") -> #N/A | L5: =IFERROR(__xludf.DUMMYFUNCTION("""COMPUTED_VALUE"""),"#N/A") -> #N/A
A6: =IFERROR(__xludf.DUMMYFUNCTION("""COMPUTED_VALUE"""),"Nebus.") -> Nebus. | B6: 0 | C6: 0 | D6: 0 | F6: =IFERROR(__xludf.DUMMYFUNCTION("""COMPUTED_VALUE"""),"#N/A") -> #N/A | H6: =IFERROR(__xludf.DUMMYFUNCTION("""COMPUTED_VALUE"""),"#N/A") -> #N/A | J6: =IFERROR(__xludf.DUMMYFUNCTION("""COMPUTED_VALUE"""),"#N/A") -> #N/A | L6: =IFERROR(__xludf.DUMMYFUNCTION("""COMPUTED_VALUE"""),"#N/A") -> #N/A
A7: =IFERROR(__xludf.DUMMYFUNCTION("""COMPUTED_VALUE"""),"Tess1509") -> Tess1509 | B7: 0 | C7: 0 | D7: 0 | F7: =IFERROR(__xludf.DUMMYFUNCTION("""COMPUTED_VALUE"""),"#N/A") -> #N/A | H7: =IFERROR(__xludf.DUMMYFUNCTION("""COMPUTED_VALUE"""),"#N/A") -> #N/A | J7: =IFERROR(__xludf.DUMMYFUNCTION("""COMPUTED_VALUE"""),"#N/A") -> #N/A | L7: =IFERROR(__xludf.DUMMYFUNCTION("""COMPUTED_VALUE"""),"#N/A") -> #N/A
A8: =IFERROR(__xludf.DUMMYFUNCTION("""COMPUTED_VALUE"""),"Troniix") -> Troniix | B8: 0 | C8: 0 | D8: 0 | F8: =IFERROR(__xludf.DUMMYFUNCTION("""COMPUTED_VALUE"""),"#N/A") -> #N/A | H8: =IFERROR(__xludf.DUMMYFUNCTION("""COMPUTED_VALUE"""),"#N/A") -> #N/A | J8: =IFERROR(__xludf.DUMMYFUNCTION("""COMPUTED_VALUE"""),"#N/A") -> #N/A | L8: =IFERROR(__xludf.DUMMYFUNCTION("""COMPUTED_VALUE"""),"#N/A") -> #N/A
A9: =IFERROR(__xludf.DUMMYFUNCTION("""COMPUTED_VALUE"""),"ZeroO") -> ZeroO | B9: 0 | C9: 0 | D9: 0 | F9: =IFERROR(__xludf.DUMMYFUNCTION("""COMPUTED_VALUE"""),"#N/A") -> #N/A | H9: =IFERROR(__xludf.DUMMYFUNCTION("""COMPUTED_VALUE"""),"#N/A") -> #N/A | J9: =IFERROR(__xludf.DUMMYFUNCTION("""COMPUTED_VALUE"""),"#N/A") -> #N/A | L9: =IFERROR(__xludf.DUMMYFUNCTION("""COMPUTED_VALUE"""),"#N/A") -> #N/A

Sheet Team_Stats_All_Time_2v2
A1: team_key | B1: games_played | C1: wins | D1: losses | E1: winrate | F1: avg_team_goals | G1: avg_team_score
A2: =IFERROR(__xludf.DUMMYFUNCTION("SORT( UNIQUE( FILTER( Raw!J2:J1000, Raw!J2:J1000<>"""", Raw!F2:F1000=""2v2"" ) ) ) "),"Aferdita + Kesny") -> Aferdita + Kesny | B2: =IFERROR(__xludf.DUMMYFUNCTION("IF(A2="""","""", IFERROR( ROWS( UNIQUE( FILTER( Raw!A:A, Raw!J:J = A2, Raw!F:F = ""2v2"" ) ) ), 0 ) )"),2.0) -> 2 | C2: =IFERROR(__xludf.DUMMYFUNCTION("IF(A2="""","""", IFERROR( ROWS( UNIQUE( FILTER( Raw!A:A, Raw!J:J = A2, Raw!I:I = ""win"", Raw!F:F = ""2v2"" ) ) ), 0 ) )"),0.0) -> 0 | D2: =IFERROR(__xludf.DUMMYFUNCTION("IF(A2="""","""", IFERROR( ROWS( UNIQUE( FILTER( Raw!A:A, Raw!J:J = A2, Raw!I:I = ""loss"", Raw!F:F = ""2v2"" ) ) ), 0 ) )"),2.0) -> 2 | E2: {=IF(A2:A1000="", , IF(B2:B1000=0, , C2:C1000 / B2:B1000) )} -> 0 | F2: =IFERROR(__xludf.DUMMYFUNCTION("IF(A2="""","""", IFERROR( AVERAGE( UNIQUE( FILTER( Raw!N:N, Raw!J:J = A2, Raw!F:F = ""2v2"" ) ) ), 0 ) )"),8.0) -> 8 | G2: =IFERROR(__xludf.DUMMYFUNCTION("IF(A2="""","""", IFERROR( AVERAGE( UNIQUE( FILTER( Raw!R:R, Raw!J:J = A2, Raw!F:F = ""2v2"" ) ) ), 0 ) )"),247.5) -> 247.5
A3: =IFERROR(__xludf.DUMMYFUNCTION("""COMPUTED_VALUE"""),"Aferdita + Malena") -> Aferdita + Malena | B3: =IFERROR(__xludf.DUMMYFUNCTION("IF(A3="""","""", IFERROR( ROWS( UNIQUE( FILTER( Raw!A:A, Raw!J:J = A3, Raw!F:F = ""2v2"" ) ) ), 0 ) )"),4.0) -> 4 | C3: =IFERROR(__xludf.DUMMYFUNCTION("IF(A3="""","""", IFERROR( ROWS( UNIQUE( FILTER( Raw!A:A, Raw!J:J = A3, Raw!I:I = ""win"", Raw!F:F = ""2v2"" ) ) ), 0 ) )"),2.0) -> 2 | D3: =IFERROR(__xludf.DUMMYFUNCTION("IF(A3="""","""", IFERROR( ROWS( UNIQUE( FILTER( Raw!A:A, Raw!J:J = A3, Raw!I:I = ""loss"", Raw!F:F = ""2v2"" ) ) ), 0 ) )"),2.0) -> 2 | E3: 0.5 | F3: =IFERROR(__xludf.DUMMYFUNCTION("IF(A3="""","""", IFERROR( AVERAGE( UNIQUE( FILTER( Raw!N:N, Raw!J:J = A3, Raw!F:F = ""2v2"" ) ) ), 0 ) )"),8.333333333333334) -> 8.3333333 | G3: =IFERROR(__xludf.DUMMYFUNCTION("IF(A3="""","""", IFERROR( AVERAGE( UNIQUE( FILTER( Raw!R:R, Raw!J:J = A3, Raw!F:F = ""2v2"" ) ) ), 0 ) )"),274.3333333333333) -> 274.33333
A4: =IFERROR(__xludf.DUMMYFUNCTION("""COMPUTED_VALUE"""),"Aferdita + Nebus.") -> Aferdita + Nebus. | B4: =IFERROR(__xludf.DUMMYFUNCTION("IF(A4="""","""", IFERROR( ROWS( UNIQUE( FILTER( Raw!A:A, Raw!J:J = A4, Raw!F:F = ""2v2"" ) ) ), 0 ) )"),1.0) -> 1 | C4: =IFERROR(__xludf.DUMMYFUNCTION("IF(A4="""","""", IFERROR( ROWS( UNIQUE( FILTER( Raw!A:A, Raw!J:J = A4, Raw!I:I = ""win"", Raw!F:F = ""2v2"" ) ) ), 0 ) )"),1.0) -> 1 | D4: =IFERROR(__xludf.DUMMYFUNCTION("IF(A4="""","""", IFERROR( ROWS( UNIQUE( FILTER( Raw!A:A, Raw!J:J = A4, Raw!I:I = ""loss"", Raw!F:F = ""2v2"" ) ) ), 0 ) )"),0.0) -> 0 | E4: 1 | F4: =IFERROR(__xludf.DUMMYFUNCTION("IF(A4="""","""", IFERROR( AVERAGE( UNIQUE( FILTER( Raw!N:N, Raw!J:J = A4, Raw!F:F = ""2v2"" ) ) ), 0 ) )"),10.0) -> 10 | G4: =IFERROR(__xludf.DUMMYFUNCTION("IF(A4="""","""", IFERROR( AVERAGE( UNIQUE( FILTER( Raw!R:R, Raw!J:J = A4, Raw!F:F = ""2v2"" ) ) ), 0 ) )"),261.0) -> 261
A5: =IFERROR(__xludf.DUMMYFUNCTION("""COMPUTED_VALUE"""),"Aferdita + ZeroO") -> Aferdita + ZeroO | B5: =IFERROR(__xludf.DUMMYFUNCTION("IF(A5="""","""", IFERROR( ROWS( UNIQUE( FILTER( Raw!A:A, Raw!J:J = A5, Raw!F:F = ""2v2"" ) ) ), 0 ) )"),1.0) -> 1 | C5: =IFERROR(__xludf.DUMMYFUNCTION("IF(A5="""","""", IFERROR( ROWS( UNIQUE( FILTER( Raw!A:A, Raw!J:J = A5, Raw!I:I = ""win"", Raw!F:F = ""2v2"" ) ) ), 0 ) )"),0.0) -> 0 | D5: =IFERROR(__xludf.DUMMYFUNCTION("IF(A5="""","""", IFERROR( ROWS( UNIQUE( FILTER( Raw!A:A, Raw!J:J = A5, Raw!I:I = ""loss"", Raw!F:F = ""2v2"" ) ) ), 0 ) )"),1.0) -> 1 | E5: 0 | F5: =IFERROR(__xludf.DUMMYFUNCTION("IF(A5="""","""", IFERROR( AVERAGE( UNIQUE( FILTER( Raw!N:N, Raw!J:J = A5, Raw!F:F = ""2v2"" ) ) ), 0 ) )"),9.0) -> 9 | G5: =IFERROR(__xludf.DUMMYFUNCTION("IF(A5="""","""", IFERROR( AVERAGE( UNIQUE( FILTER( Raw!R:R, Raw!J:J = A5, Raw!F:F = ""2v2"" ) ) ), 0 ) )"),257.0) -> 257
A6: =IFERROR(__xludf.DUMMYFUNCTION("""COMPUTED_VALUE"""),"Kesny + Malena") -> Kesny + Malena | B6: =IFERROR(__xludf.DUMMYFUNCTION("IF(A6="""","""", IFERROR( ROWS( UNIQUE( FILTER( Raw!A:A, Raw!J:J = A6, Raw!F:F = ""2v2"" ) ) ), 0 ) )"),13.0) -> 13 | C6: =IFERROR(__xludf.DUMMYFUNCTION("IF(A6="""","""", IFERROR( ROWS( UNIQUE( FILTER( Raw!A:A, Raw!J:J = A6, Raw!I:I = ""win"", Raw!F:F = ""2v2"" ) ) ), 0 ) )"),5.0) -> 5 | D6: =IFERROR(__xludf.DUMMYFUNCTION("IF(A6="""","""", IFERROR( ROWS( UNIQUE( FILTER( Raw!A:A, Raw!J:J = A6, Raw!I:I = ""loss"", Raw!F:F = ""2v2"" ) ) ), 0 ) )"),8.0) -> 8 | E6: 0.38461538 | F6: =IFERROR(__xludf.DUMMYFUNCTION("IF(A6="""","""", IFERROR( AVERAGE( UNIQUE( FILTER( Raw!N:N, Raw!J:J = A6, Raw!F:F = ""2v2"" ) ) ), 0 ) )"),8.25) -> 8.25 | G6: =IFERROR(__xludf.DUMMYFUNCTION("IF(A6="""","""", IFERROR( AVERAGE( UNIQUE( FILTER( Raw!R:R, Raw!J:J = A6, Raw!F:F = ""2v2"" ) ) ), 0 ) )"),289.53846153846155) -> 289.53846
A7: =IFERROR(__xludf.DUMMYFUNCTION("""COMPUTED_VALUE"""),"Kesny + Nebus.") -> Kesny + Nebus. | B7: =IFERROR(__xludf.DUMMYFUNCTION("IF(A7="""","""", IFERROR( ROWS( UNIQUE( FILTER( Raw!A:A, Raw!J:J = A7, Raw!F:F = ""2v2"" ) ) ), 0 ) )"),10.0) -> 10 | C7: =IFERROR(__xludf.DUMMYFUNCTION("IF(A7="""","""", IFERROR( ROWS( UNIQUE( FILTER( Raw!A:A, Raw!J:J = A7, Raw!I:I = ""win"", Raw!F:F = ""2v2"" ) ) ), 0 ) )"),4.0) -> 4 | D7: =IFERROR(__xludf.DUMMYFUNCTION("IF(A7="""","""", IFERROR( ROWS( UNIQUE( FILTER( Raw!A:A, Raw!J:J = A7, Raw!I:I = ""loss"", Raw!F:F = ""2v2"" ) ) ), 0 ) )"),6.0) -> 6 | E7: 0.4 | F7: =IFERROR(__xludf.DUMMYFUNCTION("IF(A7="""","""", IFERROR( AVERAGE( UNIQUE( FILTER( Raw!N:N, Raw!J:J = A7, Raw!F:F = ""2v2"" ) ) ), 0 ) )"),8.5) -> 8.5 | G7: =IFERROR(__xludf.DUMMYFUNCTION("IF(A7="""","""", IFERROR( AVERAGE( UNIQUE( FILTER( Raw!R:R, Raw!J:J = A7, Raw!F:F = ""2v2"" ) ) ), 0 ) )"),295.4) -> 295.4
A8: =IFERROR(__xludf.DUMMYFUNCTION("""COMPUTED_VALUE"""),"Kesny + Tess1509") -> Kesny + Tess1509 | B8: =IFERROR(__xludf.DUMMYFUNCTION("IF(A8="""","""", IFERROR( ROWS( UNIQUE( FILTER( Raw!A:A, Raw!J:J = A8, Raw!F:F = ""2v2"" ) ) ), 0 ) )"),1.0) -> 1 | C8: =IFERROR(__xludf.DUMMYFUNCTION("IF(A8="""","""", IFERROR( ROWS( UNIQUE( FILTER( Raw!A:A, Raw!J:J = A8, Raw!I:I = ""win"", Raw!F:F = ""2v2"" ) ) ), 0 ) )"),0.0) -> 0 | D8: =IFERROR(__xludf.DUMMYFUNCTION("IF(A8="""","""", IFERROR( ROWS( UNIQUE( FILTER( Raw!A:A, Raw!J:J = A8, Raw!I:I = ""loss"", Raw!F:F = ""2v2"" ) ) ), 0 ) )"),1.0) -> 1 | E8: 0 | F8: =IFERROR(__xludf.DUMMYFUNCTION("IF(A8="""","""", IFERROR( AVERAGE( UNIQUE( FILTER( Raw!N:N, Raw!J:J = A8, Raw!F:F = ""2v2"" ) ) ), 0 ) )"),8.0) -> 8 | G8: =IFERROR(__xludf.DUMMYFUNCTION("IF(A8="""","""", IFERROR( AVERAGE( UNIQUE( FILTER( Raw!R:R, Raw!J:J = A8, Raw!F:F = ""2v2"" ) ) ), 0 ) )"),240.0) -> 240
